Workbook

Sheet 1_매출손익_대시보드
B2: 매출·지출관리 스프레드시트(순이익/실적 자동계산) | 경영 실적 종합 대시보드 | J2: 💡 조회 연월(2026-11 ~ 2027-10) 또는 시작·종료일을 선택하면 요약과 그래프가 자동 갱신됩니다.
B3: 조회 연월 선택 | C3: 12개월 총 목표매출 | D3: 직접 시작일(선택) | E3: 직접 종료일(선택) | F3: 적용 시작일(자동) | G3: 적용 종료일(자동) | H3: 비용설정 누락건수 | I3: 기간설정 중복건수 | J3: 데이터/설정 종합 점검 상태
B4: 2026-11 | C4: ='5_목표매출_및_공통비용'!E19 -> 140000000 | F4: =IF(D4<>"",D4,IF(B4="전체",DATE(2026,11,1),DATE(VALUE(LEFT(B4,4)),VALUE(RIGHT(B4,2)),1))) -> 46327 | G4: =IF(E4<>"",E4,IF(B4="전체",DATE(2027,10,31),EOMONTH(DATE(VALUE(LEFT(B4,4)),VALUE(RIGHT(B4,2)),1),0))) -> 46356 | H4: =COUNTIF('2_일일매출_입력'!$J$6:$J$305,"비용 설정 필요") -> 0 | I4: =COUNTIF('3_채널별_비용설정'!$N$6:$N$55,"*중복*")+COUNTIF('3_채널별_비용설정'!$N$6:$N$55,"*오류*") -> 0 | J4: =IF(H4+I4=0,"✅ 모든 채널 비용 설정 및 기간 적용 정상","⚠️ 비용 설정 누락(" & H4 & "건) 또는 기간 중복(" & I4 & "건) 점검 필요!") -> ✅ 모든 채널 비용 설정 및 기간 적용 정상
B6: 선택기간 목표매출 (원) | D6: 총 매출액 (실제매출) | F6: 목표 달성률 (%) | H6: 총 주문건수 (미만+이상) | J6: 총비용 (공통비 제외) | L6: 총 순이익 (공통비 전) | N6: 순이익률 (공통비 전)
B7: ='5_목표매출_및_공통비용'!G19 -> 12000000 | D7: =SUMIFS('2_일일매출_입력'!$G$6:$G$305,'2_일일매출_입력'!$B$6:$B$305,">="&$F$4,'2_일일매출_입력'!$B$6:$B$305,"<="&$G$4) -> 14505000 | F7: =IFERROR(D7/B7,0) -> 1.20875 | H7: =SUMIFS('2_일일매출_입력'!$F$6:$F$305,'2_일일매출_입력'!$B$6:$B$305,">="&$F$4,'2_일일매출_입력'!$B$6:$B$305,"<="&$G$4) -> 400 | J7: =SUMIFS('2_일일매출_입력'!$P$6:$P$305,'2_일일매출_입력'!$B$6:$B$305,">="&$F$4,'2_일일매출_입력'!$B$6:$B$305,"<="&$G$4) -> 2228550 | L7: =D7-J7 -> 12276450 | N7: =IFERROR(L7/D7,0) -> 0.84635988
B8: 10kg 미만 주문건수 (건) | D8: 10kg 이상 주문건수 (건) | F8: 매출액 기준 수수료 (원) | H8: 택배·포장 건수비용 합계 | J8: 기간 공통비용 (광고·임대) | L8: 최종 순이익 (공통비 후) | N8: 최종 순이익률 (공통비 후)
B9: =SUMIFS('2_일일매출_입력'!$D$6:$D$305,'2_일일매출_입력'!$B$6:$B$305,">="&$F$4,'2_일일매출_입력'!$B$6:$B$305,"<="&$G$4) -> 279 | D9: =SUMIFS('2_일일매출_입력'!$E$6:$E$305,'2_일일매출_입력'!$B$6:$B$305,">="&$F$4,'2_일일매출_입력'!$B$6:$B$305,"<="&$G$4) -> 121 | F9: =SUMIFS('2_일일매출_입력'!$L$6:$L$305,'2_일일매출_입력'!$B$6:$B$305,">="&$F$4,'2_일일매출_입력'!$B$6:$B$305,"<="&$G$4) -> 547850 | H9: =SUMIFS('2_일일매출_입력'!$O$6:$O$305,'2_일일매출_입력'!$B$6:$B$305,">="&$F$4,'2_일일매출_입력'!$B$6:$B$305,"<="&$G$4) -> 1630700 | J9: ='5_목표매출_및_공통비용'!M26 -> 800000 | L9: =L7-J9 -> 11476450 | N9: =IFERROR(L9/D7,0) -> 0.79120648
B10: 전체 매출성과 및 채널별 비중 그래프 (실시간 자동 갱신)
B29: 월별 손익현황 (26년 11월 ~ 27년 10월) | J29: 채널별 매출 비중 및 순이익 현황 (선택 기간)
B30: 연월 | C30: 목표매출 | D30: 총 매출 | E30: 총 지출(비용) | F30: 순이익 | G30: 이익률 | H30: 총 주문건수 | J30: 채널명 | K30: 주문건수 | L30: 매출액 | M30: 비중 | N30: 순이익 | O30: 이익률
B31: 26년 11월 | C31: ='5_목표매출_및_공통비용'!E7 -> 12000000 | D31: =SUMIFS('2_일일매출_입력'!$G$6:$G$305,'2_일일매출_입력'!$B$6:$B$305,">="&'5_목표매출_및_공통비용'!C7,'2_일일매출_입력'!$B$6:$B$305,"<="&'5_목표매출_및_공통비용'!D7) -> 14505000 | E31: =SUMIFS('2_일일매출_입력'!$P$6:$P$305,'2_일일매출_입력'!$B$6:$B$305,">="&'5_목표매출_및_공통비용'!C7,'2_일일매출_입력'!$B$6:$B$305,"<="&'5_목표매출_및_공통비용'!D7) -> 2228550 | F31: =D31-E31 -> 12276450 | G31: =IFERROR(F31/D31,0) -> 0.84635988 | H31: =SUMIFS('2_일일매출_입력'!$F$6:$F$305,'2_일일매출_입력'!$B$6:$B$305,">="&'5_목표매출_및_공통비용'!C7,'2_일일매출_입력'!$B$6:$B$305,"<="&'5_목표매출_및_공통비용'!D7) -> 400 | J31: ='6_사용설명서_및_기준관리'!B6 -> 농라 | K31: =SUMIFS('2_일일매출_입력'!$F$6:$F$305,'2_일일매출_입력'!$C$6:$C$305,J31,'2_일일매출_입력'!$B$6:$B$305,">="&$F$4,'2_일일매출_입력'!$B$6:$B$305,"<="&$G$4) -> 79 | L31: =SUMIFS('2_일일매출_입력'!$G$6:$G$305,'2_일일매출_입력'!$C$6:$C$305,J31,'2_일일매출_입력'!$B$6:$B$305,">="&$F$4,'2_일일매출_입력'!$B$6:$B$305,"<="&$G$4) -> 3330000 | M31: =IFERROR(L31/$L$38,0) -> 0.22957601 | N31: =SUMIFS('2_일일매출_입력'!$Q$6:$Q$305,'2_일일매출_입력'!$C$6:$C$305,J31,'2_일일매출_입력'!$B$6:$B$305,">="&$F$4,'2_일일매출_입력'!$B$6:$B$305,"<="&$G$4) -> 2940400 | O31: =IFERROR(N31/L31,0) -> 0.883003
B32: 26년 12월 | C32: ='5_목표매출_및_공통비용'!E8 -> 15000000 | D32: =SUMIFS('2_일일매출_입력'!$G$6:$G$305,'2_일일매출_입력'!$B$6:$B$305,">="&'5_목표매출_및_공통비용'!C8,'2_일일매출_입력'!$B$6:$B$305,"<="&'5_목표매출_및_공통비용'!D8) -> 11050000 | E32: =SUMIFS('2_일일매출_입력'!$P$6:$P$305,'2_일일매출_입력'!$B$6:$B$305,">="&'5_목표매출_및_공통비용'!C8,'2_일일매출_입력'!$B$6:$B$305,"<="&'5_목표매출_및_공통비용'!D8) -> 1526100 | F32: =D32-E32 -> 9523900 | G32: =IFERROR(F32/D32,0) -> 0.8618914 | H32: =SUMIFS('2_일일매출_입력'!$F$6:$F$305,'2_일일매출_입력'!$B$6:$B$305,">="&'5_목표매출_및_공통비용'!C8,'2_일일매출_입력'!$B$6:$B$305,"<="&'5_목표매출_및_공통비용'!D8) -> 251 | J32: ='6_사용설명서_및_기준관리'!B7 -> 스마트스토어 | K32: =SUMIFS('2_일일매출_입력'!$F$6:$F$305,'2_일일매출_입력'!$C$6:$C$305,J32,'2_일일매출_입력'!$B$6:$B$305,">="&$F$4,'2_일일매출_입력'!$B$6:$B$305,"<="&$G$4) -> 60 | L32: =SUMIFS('2_일일매출_입력'!$G$6:$G$305,'2_일일매출_입력'!$C$6:$C$305,J32,'2_일일매출_입력'!$B$6:$B$305,">="&$F$4,'2_일일매출_입력'!$B$6:$B$305,"<="&$G$4) -> 2400000 | M32: =IFERROR(L32/$L$38,0) -> 0.16546019 | N32: =SUMIFS('2_일일매출_입력'!$Q$6:$Q$305,'2_일일매출_입력'!$C$6:$C$305,J32,'2_일일매출_입력'!$B$6:$B$305,">="&$F$4,'2_일일매출_입력'!$B$6:$B$305,"<="&$G$4) -> 1986400 | O32: =IFERROR(N32/L32,0) -> 0.82766667
B33: 27년 1월 | C33: ='5_목표매출_및_공통비용'!E9 -> 18000000 | D33: =SUMIFS('2_일일매출_입력'!$G$6:$G$305,'2_일일매출_입력'!$B$6:$B$305,">="&'5_목표매출_및_공통비용'!C9,'2_일일매출_입력'!$B$6:$B$305,"<="&'5_목표매출_및_공통비용'!D9) -> 13580000 | E33: =SUMIFS('2_일일매출_입력'!$P$6:$P$305,'2_일일매출_입력'!$B$6:$B$305,">="&'5_목표매출_및_공통비용'!C9,'2_일일매출_입력'!$B$6:$B$305,"<="&'5_목표매출_및_공통비용'!D9) -> 1782540 | F33: =D33-E33 -> 11797460 | G33: =IFERROR(F33/D33,0) -> 0.86873785 | H33: =SUMIFS('2_일일매출_입력'!$F$6:$F$305,'2_일일매출_입력'!$B$6:$B$305,">="&'5_목표매출_및_공통비용'!C9,'2_일일매출_입력'!$B$6:$B$305,"<="&'5_목표매출_및_공통비용'!D9) -> 329 | J33: ='6_사용설명서_및_기준관리'!B8 -> 카톡 | K33: =SUMIFS('2_일일매출_입력'!$F$6:$F$305,'2_일일매출_입력'!$C$6:$C$305,J33,'2_일일매출_입력'!$B$6:$B$305,">="&$F$4,'2_일일매출_입력'!$B$6:$B$305,"<="&$G$4) -> 53 | L33: =SUMIFS('2_일일매출_입력'!$G$6:$G$305,'2_일일매출_입력'!$C$6:$C$305,J33,'2_일일매출_입력'!$B$6:$B$305,">="&$F$4,'2_일일매출_입력'!$B$6:$B$305,"<="&$G$4) -> 2100000 | M33: =IFERROR(L33/$L$38,0) -> 0.14477766 | N33: =SUMIFS('2_일일매출_입력'!$Q$6:$Q$305,'2_일일매출_입력'!$C$6:$C$305,J33,'2_일일매출_입력'!$B$6:$B$305,">="&$F$4,'2_일일매출_입력'!$B$6:$B$305,"<="&$G$4) -> 1782500 | O33: =IFERROR(N33/L33,0) -> 0.84880952
B34: 27년 2월 | C34: ='5_목표매출_및_공통비용'!E10 -> 14000000 | D34: =SUMIFS('2_일일매출_입력'!$G$6:$G$305,'2_일일매출_입력'!$B$6:$B$305,">="&'5_목표매출_및_공통비용'!C10,'2_일일매출_입력'!$B$6:$B$305,"<="&'5_목표매출_및_공통비용'!D10) -> 7670000 | E34: =SUMIFS('2_일일매출_입력'!$P$6:$P$305,'2_일일매출_입력'!$B$6:$B$305,">="&'5_목표매출_및_공통비용'!C10,'2_일일매출_입력'!$B$6:$B$305,"<="&'5_목표매출_및_공통비용'!D10) -> 1122260 | F34: =D34-E34 -> 6547740 | G34: =IFERROR(F34/D34,0) -> 0.85368188 | H34: =SUMIFS('2_일일매출_입력'!$F$6:$F$305,'2_일일매출_입력'!$B$6:$B$305,">="&'5_목표매출_및_공통비용'!C10,'2_일일매출_입력'!$B$6:$B$305,"<="&'5_목표매출_및_공통비용'!D10) -> 170 | J34: ='6_사용설명서_및_기준관리'!B9 -> 고흥몰 | K34: =SUMIFS('2_일일매출_입력'!$F$6:$F$305,'2_일일매출_입력'!$C$6:$C$305,J34,'2_일일매출_입력'!$B$6:$B$305,">="&$F$4,'2_일일매출_입력'!$B$6:$B$305,"<="&$G$4) -> 77 | L34: =SUMIFS('2_일일매출_입력'!$G$6:$G$305,'2_일일매출_입력'!$C$6:$C$305,J34,'2_일일매출_입력'!$B$6:$B$305,">="&$F$4,'2_일일매출_입력'!$B$6:$B$305,"<="&$G$4) -> 3140000 | M34: =IFERROR(L34/$L$38,0) -> 0.21647708 | N34: =SUMIFS('2_일일매출_입력'!$Q$6:$Q$305,'2_일일매출_입력'!$C$6:$C$305,J34,'2_일일매출_입력'!$B$6:$B$305,">="&$F$4,'2_일일매출_입력'!$B$6:$B$305,"<="&$G$4) -> 2692100 | O34: =IFERROR(N34/L34,0) -> 0.85735669
B35: 27년 3월 | C35: ='5_목표매출_및_공통비용'!E11 -> 10000000 | D35: =SUMIFS('2_일일매출_입력'!$G$6:$G$305,'2_일일매출_입력'!$B$6:$B$305,">="&'5_목표매출_및_공통비용'!C11,'2_일일매출_입력'!$B$6:$B$305,"<="&'5_목표매출_및_공통비용'!D11) -> 0 | E35: =SUMIFS('2_일일매출_입력'!$P$6:$P$305,'2_일일매출_입력'!$B$6:$B$305,">="&'5_목표매출_및_공통비용'!C11,'2_일일매출_입력'!$B$6:$B$305,"<="&'5_목표매출_및_공통비용'!D11) -> 0 | F35: =D35-E35 -> 0 | G35: =IFERROR(F35/D35,0) -> 0 | H35: =SUMIFS('2_일일매출_입력'!$F$6:$F$305,'2_일일매출_입력'!$B$6:$B$305,">="&'5_목표매출_및_공통비용'!C11,'2_일일매출_입력'!$B$6:$B$305,"<="&'5_목표매출_및_공통비용'!D11) -> 0 | J35: ='6_사용설명서_및_기준관리'!B10 -> 남도장터 | K35: =SUMIFS('2_일일매출_입력'!$F$6:$F$305,'2_일일매출_입력'!$C$6:$C$305,J35,'2_일일매출_입력'!$B$6:$B$305,">="&$F$4,'2_일일매출_입력'!$B$6:$B$305,"<="&$G$4) -> 36 | L35: =SUMIFS('2_일일매출_입력'!$G$6:$G$305,'2_일일매출_입력'!$C$6:$C$305,J35,'2_일일매출_입력'!$B$6:$B$305,">="&$F$4,'2_일일매출_입력'!$B$6:$B$305,"<="&$G$4) -> 1540000 | M35: =IFERROR(L35/$L$38,0) -> 0.10617029 | N35: =SUMIFS('2_일일매출_입력'!$Q$6:$Q$305,'2_일일매출_입력'!$C$6:$C$305,J35,'2_일일매출_입력'!$B$6:$B$305,">="&$F$4,'2_일일매출_입력'!$B$6:$B$305,"<="&$G$4) -> 1301400 | O35: =IFERROR(N35/L35,0) -> 0.84506494
B36: 27년 4월 | C36: ='5_목표매출_및_공통비용'!E12 -> 9000000 | D36: =SUMIFS('2_일일매출_입력'!$G$6:$G$305,'2_일일매출_입력'!$B$6:$B$305,">="&'5_목표매출_및_공통비용'!C12,'2_일일매출_입력'!$B$6:$B$305,"<="&'5_목표매출_및_공통비용'!D12) -> 0 | E36: =SUMIFS('2_일일매출_입력'!$P$6:$P$305,'2_일일매출_입력'!$B$6:$B$305,">="&'5_목표매출_및_공통비용'!C12,'2_일일매출_입력'!$B$6:$B$305,"<="&'5_목표매출_및_공통비용'!D12) -> 0 | F36: =D36-E36 -> 0 | G36: =IFERROR(F36/D36,0) -> 0 | H36: =SUMIFS('2_일일매출_입력'!$F$6:$F$305,'2_일일매출_입력'!$B$6:$B$305,">="&'5_목표매출_및_공통비용'!C12,'2_일일매출_입력'!$B$6:$B$305,"<="&'5_목표매출_및_공통비용'!D12) -> 0 | J36: ='6_사용설명서_및_기준관리'!B11 -> 로컬푸드 | K36: =SUMIFS('2_일일매출_입력'!$F$6:$F$305,'2_일일매출_입력'!$C$6:$C$305,J36,'2_일일매출_입력'!$B$6:$B$305,">="&$F$4,'2_일일매출_입력'!$B$6:$B$305,"<="&$G$4) -> 50 | L36: =SUMIFS('2_일일매출_입력'!$G$6:$G$305,'2_일일매출_입력'!$C$6:$C$305,J36,'2_일일매출_입력'!$B$6:$B$305,">="&$F$4,'2_일일매출_입력'!$B$6:$B$305,"<="&$G$4) -> 1150000 | M36: =IFERROR(L36/$L$38,0) -> 0.079283006 | N36: =SUMIFS('2_일일매출_입력'!$Q$6:$Q$305,'2_일일매출_입력'!$C$6:$C$305,J36,'2_일일매출_입력'!$B$6:$B$305,">="&$F$4,'2_일일매출_입력'!$B$6:$B$305,"<="&$G$4) -> 1005000 | O36: =IFERROR(N36/L36,0) -> 0.87391304
B37: 27년 5월 | C37: ='5_목표매출_및_공통비용'!E13 -> 11000000 | D37: =SUMIFS('2_일일매출_입력'!$G$6:$G$305,'2_일일매출_입력'!$B$6:$B$305,">="&'5_목표매출_및_공통비용'!C13,'2_일일매출_입력'!$B$6:$B$305,"<="&'5_목표매출_및_공통비용'!D13) -> 0 | E37: =SUMIFS('2_일일매출_입력'!$P$6:$P$305,'2_일일매출_입력'!$B$6:$B$305,">="&'5_목표매출_및_공통비용'!C13,'2_일일매출_입력'!$B$6:$B$305,"<="&'5_목표매출_및_공통비용'!D13) -> 0 | F37: =D37-E37 -> 0 | G37: =IFERROR(F37/D37,0) -> 0 | H37: =SUMIFS('2_일일매출_입력'!$F$6:$F$305,'2_일일매출_입력'!$B$6:$B$305,">="&'5_목표매출_및_공통비용'!C13,'2_일일매출_입력'!$B$6:$B$305,"<="&'5_목표매출_및_공통비용'!D13) -> 0 | J37: ='6_사용설명서_및_기준관리'!B12 -> 기타 | K37: =SUMIFS('2_일일매출_입력'!$F$6:$F$305,'2_일일매출_입력'!$C$6:$C$305,J37,'2_일일매출_입력'!$B$6:$B$305,">="&$F$4,'2_일일매출_입력'!$B$6:$B$305,"<="&$G$4) -> 45 | L37: =SUMIFS('2_일일매출_입력'!$G$6:$G$305,'2_일일매출_입력'!$C$6:$C$305,J37,'2_일일매출_입력'!$B$6:$B$305,">="&$F$4,'2_일일매출_입력'!$B$6:$B$305,"<="&$G$4) -> 845000 | M37: =IFERROR(L37/$L$38,0) -> 0.058255774 | N37: =SUMIFS('2_일일매출_입력'!$Q$6:$Q$305,'2_일일매출_입력'!$C$6:$C$305,J37,'2_일일매출_입력'!$B$6:$B$305,">="&$F$4,'2_일일매출_입력'!$B$6:$B$305,"<="&$G$4) -> 568650 | O37: =IFERROR(N37/L37,0) -> 0.67295858
B38: 27년 6월 | C38: ='5_목표매출_및_공통비용'!E14 -> 8000000 | D38: =SUMIFS('2_일일매출_입력'!$G$6:$G$305,'2_일일매출_입력'!$B$6:$B$305,">="&'5_목표매출_및_공통비용'!C14,'2_일일매출_입력'!$B$6:$B$305,"<="&'5_목표매출_및_공통비용'!D14) -> 0 | E38: =SUMIFS('2_일일매출_입력'!$P$6:$P$305,'2_일일매출_입력'!$B$6:$B$305,">="&'5_목표매출_및_공통비용'!C14,'2_일일매출_입력'!$B$6:$B$305,"<="&'5_목표매출_및_공통비용'!D14) -> 0 | F38: =D38-E38 -> 0 | G38: =IFERROR(F38/D38,0) -> 0 | H38: =SUMIFS('2_일일매출_입력'!$F$6:$F$305,'2_일일매출_입력'!$B$6:$B$305,">="&'5_목표매출_및_공통비용'!C14,'2_일일매출_입력'!$B$6:$B$305,"<="&'5_목표매출_및_공통비용'!D14) -> 0 | J38: 합계 | K38: =SUM(K31:K37) -> 400 | L38: =SUM(L31:L37) -> 14505000 | M38: =IFERROR(SUM(M31:M37),0) -> 1 | N38: =SUM(N31:N37) -> 12276450 | O38: =IFERROR(N38/L38,0) -> 0.84635988
B39: 27년 7월 | C39: ='5_목표매출_및_공통비용'!E15 -> 7000000 | D39: =SUMIFS('2_일일매출_입력'!$G$6:$G$305,'2_일일매출_입력'!$B$6:$B$305,">="&'5_목표매출_및_공통비용'!C15,'2_일일매출_입력'!$B$6:$B$305,"<="&'5_목표매출_및_공통비용'!D15) -> 0 | E39: =SUMIFS('2_일일매출_입력'!$P$6:$P$305,'2_일일매출_입력'!$B$6:$B$305,">="&'5_목표매출_및_공통비용'!C15,'2_일일매출_입력'!$B$6:$B$305,"<="&'5_목표매출_및_공통비용'!D15) -> 0 | F39: =D39-E39 -> 0 | G39: =IFERROR(F39/D39,0) -> 0 | H39: =SUMIFS('2_일일매출_입력'!$F$6:$F$305,'2_일일매출_입력'!$B$6:$B$305,">="&'5_목표매출_및_공통비용'!C15,'2_일일매출_입력'!$B$6:$B$305,"<="&'5_목표매출_및_공통비용'!D15) -> 0
B40: 27년 8월 | C40: ='5_목표매출_및_공통비용'!E16 -> 9000000 | D40: =SUMIFS('2_일일매출_입력'!$G$6:$G$305,'2_일일매출_입력'!$B$6:$B$305,">="&'5_목표매출_및_공통비용'!C16,'2_일일매출_입력'!$B$6:$B$305,"<="&'5_목표매출_및_공통비용'!D16) -> 0 | E40: =SUMIFS('2_일일매출_입력'!$P$6:$P$305,'2_일일매출_입력'!$B$6:$B$305,">="&'5_목표매출_및_공통비용'!C16,'2_일일매출_입력'!$B$6:$B$305,"<="&'5_목표매출_및_공통비용'!D16) -> 0 | F40: =D40-E40 -> 0 | G40: =IFERROR(F40/D40,0) -> 0 | H40: =SUMIFS('2_일일매출_입력'!$F$6:$F$305,'2_일일매출_입력'!$B$6:$B$305,">="&'5_목표매출_및_공통비용'!C16,'2_일일매출_입력'!$B$6:$B$305,"<="&'5_목표매출_및_공통비용'!D16) -> 0 | J40: 구분 | K40: 목표매출 | L40: 총 매출액 | M40: 총 순이익 | N40: 최종순이익(공통비후)
B41: 27년 9월 | C41: ='5_목표매출_및_공통비용'!E17 -> 16000000 | D41: =SUMIFS('2_일일매출_입력'!$G$6:$G$305,'2_일일매출_입력'!$B$6:$B$305,">="&'5_목표매출_및_공통비용'!C17,'2_일일매출_입력'!$B$6:$B$305,"<="&'5_목표매출_및_공통비용'!D17) -> 0 | E41: =SUMIFS('2_일일매출_입력'!$P$6:$P$305,'2_일일매출_입력'!$B$6:$B$305,">="&'5_목표매출_및_공통비용'!C17,'2_일일매출_입력'!$B$6:$B$305,"<="&'5_목표매출_및_공통비용'!D17) -> 0 | F41: =D41-E41 -> 0 | G41: =IFERROR(F41/D41,0) -> 0 | H41: =SUMIFS('2_일일매출_입력'!$F$6:$F$305,'2_일일매출_입력'!$B$6:$B$305,">="&'5_목표매출_및_공통비용'!C17,'2_일일매출_입력'!$B$6:$B$305,"<="&'5_목표매출_및_공통비용'!D17) -> 0 | J41: 전체 매출성과 | K41: =B7 -> 12000000 | L41: =D7 -> 14505000 | M41: =L7 -> 12276450 | N41: =L9 -> 11476450
B42: 27년 10월 | C42: ='5_목표매출_및_공통비용'!E18 -> 11000000 | D42: =SUMIFS('2_일일매출_입력'!$G$6:$G$305,'2_일일매출_입력'!$B$6:$B$305,">="&'5_목표매출_및_공통비용'!C18,'2_일일매출_입력'!$B$6:$B$305,"<="&'5_목표매출_및_공통비용'!D18) -> 0 | E42: =SUMIFS('2_일일매출_입력'!$P$6:$P$305,'2_일일매출_입력'!$B$6:$B$305,">="&'5_목표매출_및_공통비용'!C18,'2_일일매출_입력'!$B$6:$B$305,"<="&'5_목표매출_및_공통비용'!D18) -> 0 | F42: =D42-E42 -> 0 | G42: =IFERROR(F42/D42,0) -> 0 | H42: =SUMIFS('2_일일매출_입력'!$F$6:$F$305,'2_일일매출_입력'!$B$6:$B$305,">="&'5_목표매출_및_공통비용'!C18,'2_일일매출_입력'!$B$6:$B$305,"<="&'5_목표매출_및_공통비용'!D18) -> 0
B43: 12개월 합계 | C43: =SUM(C31:C42) -> 140000000 | D43: =SUM(D31:D42) -> 46805000 | E43: =SUM(E31:E42) -> 6659450 | F43: =D43-E43 -> 40145550 | G43: =IFERROR(F43/D43,0) -> 0.85771926 | H43: =SUM(H31:H42) -> 1150

Sheet 2_일일매출_입력
B2: 매출·지출관리 스프레드시트(순이익/실적 자동계산) | 일일 매출·주문내역 입력
B3: 💡 [입력 안내] ① 노란색 열(매출일자, 판매채널, 10kg 미만 주문건수, 10kg 이상 주문건수, 일일 매출액, 추가비용, 비고)만 입력하세요. ② 10kg 미만과 10kg 이상 주문건수에 따라 각각 다른 택배비와 포장비(박스+포장비닐+리플렛)가 자동 계산됩니다. ③ 기본 택배비·박스·비닐·리플렛 비용은 자동 계산되므로 [추가 비용] 칸에 중복 입력하지 마세요.
B4: 누적 합계 | C4: =COUNTA(B6:B305)&"건" -> 23건 | D4: =SUM(D6:D305) -> 802 | E4: =SUM(E6:E305) -> 348 | F4: =SUM(F6:F305) -> 1150 | G4: =SUM(G6:G305) -> 46805000 | H4: =SUM(H6:H305) -> 70000 | I4: ← 매출·주문 입력 | 비용·손익 자동계산 → | J4: =COUNTIF(J6:J305,"비용 설정 필요")&"건 누락" -> 0건 누락 | K4: - | L4: =SUMIF(L6:L305,">=0") -> 1842850 | M4: - | N4: - | O4: =SUMIF(O6:O305,">=0") -> 4746600 | P4: =SUMIF(P6:P305,">=0") -> 6659450 | Q4: =G4-P4 -> 40145550 | R4: =IFERROR(Q4/G4,0) -> 0.85771926
B5: 매출일자 (달력/날짜입력) | C5: 판매채널 (드롭다운) | D5: 10kg 미만 주문건수(건) | E5: 10kg 이상 주문건수(건) | F5: 총 주문건수 (자동합산) | G5: 일일 매출액 (할인반영 실매출) | H5: 추가 비용 (특이발생분) | I5: 비고 (메모) | J5: 비용설정 상태 (자동검증) | K5: 적용 수수료율 (자동조회) | L5: 매출액 수수료 (자동계산) | M5: 10kg 미만 1건당 비용 | N5: 10kg 이상 1건당 비용 | O5: 주문건수 비용 합계(택배+포장) | P5: 총 지출(총비용) (수수료+건수비+추가) | Q5: 순이익 (매출-총비용) | R5: 순이익률 (순이익÷매출)
B6: 46328 | C6: 농라 | D6: 24 | E6: 12 | F6: =IF(AND(B6="",C6=""),"",SUM(D6:E6)) -> 36 | G6: 1480000 | H6: 0 | I6: [예시] 11월 첫째주 햇유자·특산물 공동구매 | J6: =IF(AND(B6="",C6=""),"",IF(OR(B6="",C6=""),"비용 설정 필요",IF(COUNTIFS('3_채널별_비용설정'!$C$6:$C$55,C6,'3_채널별_비용설정'!$D$6:$D$55,"<="&B6,'3_채널별_비용설정'!$O$6:$O$55,">="&B6)=0,"비용 설정 필요",IF(COUNTIFS('3_채널별_비용설정'!$C$6:$C$55,C6,'3_채널별_비용설정'!$D$6:$D$55,"<="&B6,'3_채널별_비용설정'!$O$6:$O$55,">="&B6)>1,"기간 중복 확인","정상")))) -> 정상 | K6: =IF(J6="","",IF(J6<>"정상","비용 설정 필요",SUMIFS('3_채널별_비용설정'!$F$6:$F$55,'3_채널별_비용설정'!$C$6:$C$55,C6,'3_채널별_비용설정'!$D$6:$D$55,"<="&B6,'3_채널별_비용설정'!$O$6:$O$55,">="&B6))) -> 0 | L6: =IF(J6="","",IF(J6<>"정상","비용 설정 필요",ROUND(G6*K6,0))) -> 0 | M6: =IF(J6="","",IF(J6<>"정상","비용 설정 필요",SUMIFS('3_채널별_비용설정'!$L$6:$L$55,'3_채널별_비용설정'!$C$6:$C$55,C6,'3_채널별_비용설정'!$D$6:$D$55,"<="&B6,'3_채널별_비용설정'!$O$6:$O$55,">="&B6))) -> 4400 | N6: =IF(J6="","",IF(J6<>"정상","비용 설정 필요",SUMIFS('3_채널별_비용설정'!$M$6:$M$55,'3_채널별_비용설정'!$C$6:$C$55,C6,'3_채널별_비용설정'!$D$6:$D$55,"<="&B6,'3_채널별_비용설정'!$O$6:$O$55,">="&B6))) -> 5400 | O6: =IF(J6="","",IF(J6<>"정상","비용 설정 필요",(D6*M6)+(E6*N6))) -> 170400 | P6: =IF(J6="","",IF(J6<>"정상","비용 설정 필요",L6+O6+H6)) -> 170400 | Q6: =IF(J6="","",IF(J6<>"정상","비용 설정 필요",G6-P6)) -> 1309600 | R6: =IF(J6="","",IF(J6<>"정상","비용 설정 필요",IFERROR(Q6/G6,0))) -> 0.88486486
B7: 46330 | C7: 고흥몰 | D7: 30 | E7: 10 | F7: =IF(AND(B7="",C7=""),"",SUM(D7:E7)) -> 40 | G7: 1620000 | H7: 0 | I7: [예시] 고흥몰 가을 수확 기획전 | J7: =IF(AND(B7="",C7=""),"",IF(OR(B7="",C7=""),"비용 설정 필요",IF(COUNTIFS('3_채널별_비용설정'!$C$6:$C$55,C7,'3_채널별_비용설정'!$D$6:$D$55,"<="&B7,'3_채널별_비용설정'!$O$6:$O$55,">="&B7)=0,"비용 설정 필요",IF(COUNTIFS('3_채널별_비용설정'!$C$6:$C$55,C7,'3_채널별_비용설정'!$D$6:$D$55,"<="&B7,'3_채널별_비용설정'!$O$6:$O$55,">="&B7)>1,"기간 중복 확인","정상")))) -> 정상 | K7: =IF(J7="","",IF(J7<>"정상","비용 설정 필요",SUMIFS('3_채널별_비용설정'!$F$6:$F$55,'3_채널별_비용설정'!$C$6:$C$55,C7,'3_채널별_비용설정'!$D$6:$D$55,"<="&B7,'3_채널별_비용설정'!$O$6:$O$55,">="&B7))) -> 0.04 | L7: =IF(J7="","",IF(J7<>"정상","비용 설정 필요",ROUND(G7*K7,0))) -> 64800 | M7: =IF(J7="","",IF(J7<>"정상","비용 설정 필요",SUMIFS('3_채널별_비용설정'!$L$6:$L$55,'3_채널별_비용설정'!$C$6:$C$55,C7,'3_채널별_비용설정'!$D$6:$D$55,"<="&B7,'3_채널별_비용설정'!$O$6:$O$55,">="&B7))) -> 3900 | N7: =IF(J7="","",IF(J7<>"정상","비용 설정 필요",SUMIFS('3_채널별_비용설정'!$M$6:$M$55,'3_채널별_비용설정'!$C$6:$C$55,C7,'3_채널별_비용설정'!$D$6:$D$55,"<="&B7,'3_채널별_비용설정'!$O$6:$O$55,">="&B7))) -> 4900 | O7: =IF(J7="","",IF(J7<>"정상","비용 설정 필요",(D7*M7)+(E7*N7))) -> 166000 | P7: =IF(J7="","",IF(J7<>"정상","비용 설정 필요",L7+O7+H7)) -> 230800 | Q7: =IF(J7="","",IF(J7<>"정상","비용 설정 필요",G7-P7)) -> 1389200 | R7: =IF(J7="","",IF(J7<>"정상","비용 설정 필요",IFERROR(Q7/G7,0))) -> 0.85753086
B8: 46332 | C8: 카톡 | D8: 18 | E8: 7 | F8: =IF(AND(B8="",C8=""),"",SUM(D8:E8)) -> 25 | G8: 980000 | H8: 0 | I8: [예시] 단골 고객 카톡 알림톡 주문 | J8: =IF(AND(B8="",C8=""),"",IF(OR(B8="",C8=""),"비용 설정 필요",IF(COUNTIFS('3_채널별_비용설정'!$C$6:$C$55,C8,'3_채널별_비용설정'!$D$6:$D$55,"<="&B8,'3_채널별_비용설정'!$O$6:$O$55,">="&B8)=0,"비용 설정 필요",IF(COUNTIFS('3_채널별_비용설정'!$C$6:$C$55,C8,'3_채널별_비용설정'!$D$6:$D$55,"<="&B8,'3_채널별_비용설정'!$O$6:$O$55,">="&B8)>1,"기간 중복 확인","정상")))) -> 정상 | K8: =IF(J8="","",IF(J8<>"정상","비용 설정 필요",SUMIFS('3_채널별_비용설정'!$F$6:$F$55,'3_채널별_비용설정'!$C$6:$C$55,C8,'3_채널별_비용설정'!$D$6:$D$55,"<="&B8,'3_채널별_비용설정'!$O$6:$O$55,">="&B8))) -> 0.033 | L8: =IF(J8="","",IF(J8<>"정상","비용 설정 필요",ROUND(G8*K8,0))) -> 32340 | M8: =IF(J8="","",IF(J8<>"정상","비용 설정 필요",SUMIFS('3_채널별_비용설정'!$L$6:$L$55,'3_채널별_비용설정'!$C$6:$C$55,C8,'3_채널별_비용설정'!$D$6:$D$55,"<="&B8,'3_채널별_비용설정'!$O$6:$O$55,">="&B8))) -> 4400 | N8: =IF(J8="","",IF(J8<>"정상","비용 설정 필요",SUMIFS('3_채널별_비용설정'!$M$6:$M$55,'3_채널별_비용설정'!$C$6:$C$55,C8,'3_채널별_비용설정'!$D$6:$D$55,"<="&B8,'3_채널별_비용설정'!$O$6:$O$55,">="&B8))) -> 5400 | O8: =IF(J8="","",IF(J8<>"정상","비용 설정 필요",(D8*M8)+(E8*N8))) -> 117000 | P8: =IF(J8="","",IF(J8<>"정상","비용 설정 필요",L8+O8+H8)) -> 149340 | Q8: =IF(J8="","",IF(J8<>"정상","비용 설정 필요",G8-P8)) -> 830660 | R8: =IF(J8="","",IF(J8<>"정상","비용 설정 필요",IFERROR(Q8/G8,0))) -> 0.84761224
B9: 46334 | C9: 남도장터 | D9: 22 | E9: 14 | F9: =IF(AND(B9="",C9=""),"",SUM(D9:E9)) -> 36 | G9: 1540000 | H9: 0 | I9: [예시] 남도장터 주말 할인전 | J9: =IF(AND(B9="",C9=""),"",IF(OR(B9="",C9=""),"비용 설정 필요",IF(COUNTIFS('3_채널별_비용설정'!$C$6:$C$55,C9,'3_채널별_비용설정'!$D$6:$D$55,"<="&B9,'3_채널별_비용설정'!$O$6:$O$55,">="&B9)=0,"비용 설정 필요",IF(COUNTIFS('3_채널별_비용설정'!$C$6:$C$55,C9,'3_채널별_비용설정'!$D$6:$D$55,"<="&B9,'3_채널별_비용설정'!$O$6:$O$55,">="&B9)>1,"기간 중복 확인","정상")))) -> 정상 | K9: =IF(J9="","",IF(J9<>"정상","비용 설정 필요",SUMIFS('3_채널별_비용설정'!$F$6:$F$55,'3_채널별_비용설정'!$C$6:$C$55,C9,'3_채널별_비용설정'!$D$6:$D$55,"<="&B9,'3_채널별_비용설정'!$O$6:$O$55,">="&B9))) -> 0.05 | L9: =IF(J9="","",IF(J9<>"정상","비용 설정 필요",ROUND(G9*K9,0))) -> 77000 | M9: =IF(J9="","",IF(J9<>"정상","비용 설정 필요",SUMIFS('3_채널별_비용설정'!$L$6:$L$55,'3_채널별_비용설정'!$C$6:$C$55,C9,'3_채널별_비용설정'!$D$6:$D$55,"<="&B9,'3_채널별_비용설정'!$O$6:$O$55,">="&B9))) -> 4100 | N9: =IF(J9="","",IF(J9<>"정상","비용 설정 필요",SUMIFS('3_채널별_비용설정'!$M$6:$M$55,'3_채널별_비용설정'!$C$6:$C$55,C9,'3_채널별_비용설정'!$D$6:$D$55,"<="&B9,'3_채널별_비용설정'!$O$6:$O$55,">="&B9))) -> 5100 | O9: =IF(J9="","",IF(J9<>"정상","비용 설정 필요",(D9*M9)+(E9*N9))) -> 161600 | P9: =IF(J9="","",IF(J9<>"정상","비용 설정 필요",L9+O9+H9)) -> 238600 | Q9: =IF(J9="","",IF(J9<>"정상","비용 설정 필요",G9-P9)) -> 1301400 | R9: =IF(J9="","",IF(J9<>"정상","비용 설정 필요",IFERROR(Q9/G9,0))) -> 0.84506494
B10: 46337 | C10: 로컬푸드 | D10: 45 | E10: 5 | F10: =IF(AND(B10="",C10=""),"",SUM(D10:E10)) -> 50 | G10: 1150000 | H10: 0 | I10: [예시] 로컬푸드 직매장 출하 | J10: =IF(AND(B10="",C10=""),"",IF(OR(B10="",C10=""),"비용 설정 필요",IF(COUNTIFS('3_채널별_비용설정'!$C$6:$C$55,C10,'3_채널별_비용설정'!$D$6:$D$55,"<="&B10,'3_채널별_비용설정'!$O$6:$O$55,">="&B10)=0,"비용 설정 필요",IF(COUNTIFS('3_채널별_비용설정'!$C$6:$C$55,C10,'3_채널별_비용설정'!$D$6:$D$55,"<="&B10,'3_채널별_비용설정'!$O$6:$O$55,">="&B10)>1,"기간 중복 확인","정상")))) -> 정상 | K10: =IF(J10="","",IF(J10<>"정상","비용 설정 필요",SUMIFS('3_채널별_비용설정'!$F$6:$F$55,'3_채널별_비용설정'!$C$6:$C$55,C10,'3_채널별_비용설정'!$D$6:$D$55,"<="&B10,'3_채널별_비용설정'!$O$6:$O$55,">="&B10))) -> 0.1 | L10: =IF(J10="","",IF(J10<>"정상","비용 설정 필요",ROUND(G10*K10,0))) -> 115000 | M10: =IF(J10="","",IF(J10<>"정상","비용 설정 필요",SUMIFS('3_채널별_비용설정'!$L$6:$L$55,'3_채널별_비용설정'!$C$6:$C$55,C10,'3_채널별_비용설정'!$D$6:$D$55,"<="&B10,'3_채널별_비용설정'!$O$6:$O$55,">="&B10))) -> 600 | N10: =IF(J10="","",IF(J10<>"정상","비용 설정 필요",SUMIFS('3_채널별_비용설정'!$M$6:$M$55,'3_채널별_비용설정'!$C$6:$C$55,C10,'3_채널별_비용설정'!$D$6:$D$55,"<="&B10,'3_채널별_비용설정'!$O$6:$O$55,">="&B10))) -> 600 | O10: =IF(J10="","",IF(J10<>"정상","비용 설정 필요",(D10*M10)+(E10*N10))) -> 30000 | P10: =IF(J10="","",IF(J10<>"정상","비용 설정 필요",L10+O10+H10)) -> 145000 | Q10: =IF(J10="","",IF(J10<>"정상","비용 설정 필요",G10-P10)) -> 1005000 | R10: =IF(J10="","",IF(J10<>"정상","비용 설정 필요",IFERROR(Q10/G10,0))) -> 0.87391304
B11: 46340 | C11: 스마트스토어 | D11: 20 | E11: 10 | F11: =IF(AND(B11="",C11=""),"",SUM(D11:E11)) -> 30 | G11: 1200000 | H11: 0 | I11: [단가변경 전 확인] 11/15 이전: 수수료 5.5%, 미만 4,200원 / 이상 5,200원 적용 | J11: =IF(AND(B11="",C11=""),"",IF(OR(B11="",C11=""),"비용 설정 필요",IF(COUNTIFS('3_채널별_비용설정'!$C$6:$C$55,C11,'3_채널별_비용설정'!$D$6:$D$55,"<="&B11,'3_채널별_비용설정'!$O$6:$O$55,">="&B11)=0,"비용 설정 필요",IF(COUNTIFS('3_채널별_비용설정'!$C$6:$C$55,C11,'3_채널별_비용설정'!$D$6:$D$55,"<="&B11,'3_채널별_비용설정'!$O$6:$O$55,">="&B11)>1,"기간 중복 확인","정상")))) -> 정상 | K11: =IF(J11="","",IF(J11<>"정상","비용 설정 필요",SUMIFS('3_채널별_비용설정'!$F$6:$F$55,'3_채널별_비용설정'!$C$6:$C$55,C11,'3_채널별_비용설정'!$D$6:$D$55,"<="&B11,'3_채널별_비용설정'!$O$6:$O$55,">="&B11))) -> 0.055 | L11: =IF(J11="","",IF(J11<>"정상","비용 설정 필요",ROUND(G11*K11,0))) -> 66000 | M11: =IF(J11="","",IF(J11<>"정상","비용 설정 필요",SUMIFS('3_채널별_비용설정'!$L$6:$L$55,'3_채널별_비용설정'!$C$6:$C$55,C11,'3_채널별_비용설정'!$D$6:$D$55,"<="&B11,'3_채널별_비용설정'!$O$6:$O$55,">="&B11))) -> 4100 | N11: =IF(J11="","",IF(J11<>"정상","비용 설정 필요",SUMIFS('3_채널별_비용설정'!$M$6:$M$55,'3_채널별_비용설정'!$C$6:$C$55,C11,'3_채널별_비용설정'!$D$6:$D$55,"<="&B11,'3_채널별_비용설정'!$O$6:$O$55,">="&B11))) -> 5100 | O11: =IF(J11="","",IF(J11<>"정상","비용 설정 필요",(D11*M11)+(E11*N11))) -> 133000 | P11: =IF(J11="","",IF(J11<>"정상","비용 설정 필요",L11+O11+H11)) -> 199000 | Q11: =IF(J11="","",IF(J11<>"정상","비용 설정 필요",G11-P11)) -> 1001000 | R11: =IF(J11="","",IF(J11<>"정상","비용 설정 필요",IFERROR(Q11/G11,0))) -> 0.83416667
B12: 46343 | C12: 스마트스토어 | D12: 20 | E12: 10 | F12: =IF(AND(B12="",C12=""),"",SUM(D12:E12)) -> 30 | G12: 1200000 | H12: 0 | I12: [단가변경 후 확인] 11/16 이후: 수수료 5.8%, 미만 4,600원 / 이상 5,600원 자동 적용! | J12: =IF(AND(B12="",C12=""),"",IF(OR(B12="",C12=""),"비용 설정 필요",IF(COUNTIFS('3_채널별_비용설정'!$C$6:$C$55,C12,'3_채널별_비용설정'!$D$6:$D$55,"<="&B12,'3_채널별_비용설정'!$O$6:$O$55,">="&B12)=0,"비용 설정 필요",IF(COUNTIFS('3_채널별_비용설정'!$C$6:$C$55,C12,'3_채널별_비용설정'!$D$6:$D$55,"<="&B12,'3_채널별_비용설정'!$O$6:$O$55,">="&B12)>1,"기간 중복 확인","정상")))) -> 정상 | K12: =IF(J12="","",IF(J12<>"정상","비용 설정 필요",SUMIFS('3_채널별_비용설정'!$F$6:$F$55,'3_채널별_비용설정'!$C$6:$C$55,C12,'3_채널별_비용설정'!$D$6:$D$55,"<="&B12,'3_채널별_비용설정'!$O$6:$O$55,">="&B12))) -> 0.058 | L12: =IF(J12="","",IF(J12<>"정상","비용 설정 필요",ROUND(G12*K12,0))) -> 69600 | M12: =IF(J12="","",IF(J12<>"정상","비용 설정 필요",SUMIFS('3_채널별_비용설정'!$L$6:$L$55,'3_채널별_비용설정'!$C$6:$C$55,C12,'3_채널별_비용설정'!$D$6:$D$55,"<="&B12,'3_채널별_비용설정'!$O$6:$O$55,">="&B12))) -> 4500 | N12: =IF(J12="","",IF(J12<>"정상","비용 설정 필요",SUMIFS('3_채널별_비용설정'!$M$6:$M$55,'3_채널별_비용설정'!$C$6:$C$55,C12,'3_채널별_비용설정'!$D$6:$D$55,"<="&B12,'3_채널별_비용설정'!$O$6:$O$55,">="&B12))) -> 5500 | O12: =IF(J12="","",IF(J12<>"정상","비용 설정 필요",(D12*M12)+(E12*N12))) -> 145000 | P12: =IF(J12="","",IF(J12<>"정상","비용 설정 필요",L12+O12+H12)) -> 214600 | Q12: =IF(J12="","",IF(J12<>"정상","비용 설정 필요",G12-P12)) -> 985400 | R12: =IF(J12="","",IF(J12<>"정상","비용 설정 필요",IFERROR(Q12/G12,0))) -> 0.82116667
B13: 46346 | C13: 농라 | D13: 28 | E13: 15 | F13: =IF(AND(B13="",C13=""),"",SUM(D13:E13)) -> 43 | G13: 1850000 | H13: 15000 | I13: [예시] 대용량 10kg 이상 주문 급증 (완충재 추가비용 반영) | J13: =IF(AND(B13="",C13=""),"",IF(OR(B13="",C13=""),"비용 설정 필요",IF(COUNTIFS('3_채널별_비용설정'!$C$6:$C$55,C13,'3_채널별_비용설정'!$D$6:$D$55,"<="&B13,'3_채널별_비용설정'!$O$6:$O$55,">="&B13)=0,"비용 설정 필요",IF(COUNTIFS('3_채널별_비용설정'!$C$6:$C$55,C13,'3_채널별_비용설정'!$D$6:$D$55,"<="&B13,'3_채널별_비용설정'!$O$6:$O$55,">="&B13)>1,"기간 중복 확인","정상")))) -> 정상 | K13: =IF(J13="","",IF(J13<>"정상","비용 설정 필요",SUMIFS('3_채널별_비용설정'!$F$6:$F$55,'3_채널별_비용설정'!$C$6:$C$55,C13,'3_채널별_비용설정'!$D$6:$D$55,"<="&B13,'3_채널별_비용설정'!$O$6:$O$55,">="&B13))) -> 0 | L13: =IF(J13="","",IF(J13<>"정상","비용 설정 필요",ROUND(G13*K13,0))) -> 0 | M13: =IF(J13="","",IF(J13<>"정상","비용 설정 필요",SUMIFS('3_채널별_비용설정'!$L$6:$L$55,'3_채널별_비용설정'!$C$6:$C$55,C13,'3_채널별_비용설정'!$D$6:$D$55,"<="&B13,'3_채널별_비용설정'!$O$6:$O$55,">="&B13))) -> 4400 | N13: =IF(J13="","",IF(J13<>"정상","비용 설정 필요",SUMIFS('3_채널별_비용설정'!$M$6:$M$55,'3_채널별_비용설정'!$C$6:$C$55,C13,'3_채널별_비용설정'!$D$6:$D$55,"<="&B13,'3_채널별_비용설정'!$O$6:$O$55,">="&B13))) -> 5400 | O13: =IF(J13="","",IF(J13<>"정상","비용 설정 필요",(D13*M13)+(E13*N13))) -> 204200 | P13: =IF(J13="","",IF(J13<>"정상","비용 설정 필요",L13+O13+H13)) -> 219200 | Q13: =IF(J13="","",IF(J13<>"정상","비용 설정 필요",G13-P13)) -> 1630800 | R13: =IF(J13="","",IF(J13<>"정상","비용 설정 필요",IFERROR(Q13/G13,0))) -> 0.88151351
B14: 46348 | C14: 기타 | D14: 12 | E14: 8 | F14: =IF(AND(B14="",C14=""),"",SUM(D14:E14)) -> 20 | G14: 750000 | H14: 0 | I14: [예시] 전화 주문 단체 발송 | J14: =IF(AND(B14="",C14=""),"",IF(OR(B14="",C14=""),"비용 설정 필요",IF(COUNTIFS('3_채널별_비용설정'!$C$6:$C$55,C14,'3_채널별_비용설정'!$D$6:$D$55,"<="&B14,'3_채널별_비용설정'!$O$6:$O$55,">="&B14)=0,"비용 설정 필요",IF(COUNTIFS('3_채널별_비용설정'!$C$6:$C$55,C14,'3_채널별_비용설정'!$D$6:$D$55,"<="&B14,'3_채널별_비용설정'!$O$6:$O$55,">="&B14)>1,"기간 중복 확인","정상")))) -> 정상 | K14: =IF(J14="","",IF(J14<>"정상","비용 설정 필요",SUMIFS('3_채널별_비용설정'!$F$6:$F$55,'3_채널별_비용설정'!$C$6:$C$55,C14,'3_채널별_비용설정'!$D$6:$D$55,"<="&B14,'3_채널별_비용설정'!$O$6:$O$55,">="&B14))) -> 0.03 | L14: =IF(J14="","",IF(J14<>"정상","비용 설정 필요",ROUND(G14*K14,0))) -> 22500 | M14: =IF(J14="","",IF(J14<>"정상","비용 설정 필요",SUMIFS('3_채널별_비용설정'!$L$6:$L$55,'3_채널별_비용설정'!$C$6:$C$55,C14,'3_채널별_비용설정'!$D$6:$D$55,"<="&B14,'3_채널별_비용설정'!$O$6:$O$55,">="&B14))) -> 4400 | N14: =IF(J14="","",IF(J14<>"정상","비용 설정 필요",SUMIFS('3_채널별_비용설정'!$M$6:$M$55,'3_채널별_비용설정'!$C$6:$C$55,C14,'3_채널별_비용설정'!$D$6:$D$55,"<="&B14,'3_채널별_비용설정'!$O$6:$O$55,">="&B14))) -> 5400 | O14: =IF(J14="","",IF(J14<>"정상","비용 설정 필요",(D14*M14)+(E14*N14))) -> 96000 | P14: =IF(J14="","",IF(J14<>"정상","비용 설정 필요",L14+O14+H14)) -> 118500 | Q14: =IF(J14="","",IF(J14<>"정상","비용 설정 필요",G14-P14)) -> 631500 | R14: =IF(J14="","",IF(J14<>"정상","비용 설정 필요",IFERROR(Q14/G14,0))) -> 0.842
B15: 46351 | C15: 기타 | D15: 15 | E15: 10 | F15: =IF(AND(B15="",C15=""),"",SUM(D15:E15)) -> 25 | G15: 95000 | H15: 35000 | I15: [적자 구분 예시] 파격 샘플행사 및 파손 재발송비로 인한 일시 적자 | J15: =IF(AND(B15="",C15=""),"",IF(OR(B15="",C15=""),"비용 설정 필요",IF(COUNTIFS('3_채널별_비용설정'!$C$6:$C$55,C15,'3_채널별_비용설정'!$D$6:$D$55,"<="&B15,'3_채널별_비용설정'!$O$6:$O$55,">="&B15)=0,"비용 설정 필요",IF(COUNTIFS('3_채널별_비용설정'!$C$6:$C$55,C15,'3_채널별_비용설정'!$D$6:$D$55,"<="&B15,'3_채널별_비용설정'!$O$6:$O$55,">="&B15)>1,"기간 중복 확인","정상")))) -> 정상 | K15: =IF(J15="","",IF(J15<>"정상","비용 설정 필요",SUMIFS('3_채널별_비용설정'!$F$6:$F$55,'3_채널별_비용설정'!$C$6:$C$55,C15,'3_채널별_비용설정'!$D$6:$D$55,"<="&B15,'3_채널별_비용설정'!$O$6:$O$55,">="&B15))) -> 0.03 | L15: =IF(J15="","",IF(J15<>"정상","비용 설정 필요",ROUND(G15*K15,0))) -> 2850 | M15: =IF(J15="","",IF(J15<>"정상","비용 설정 필요",SUMIFS('3_채널별_비용설정'!$L$6:$L$55,'3_채널별_비용설정'!$C$6:$C$55,C15,'3_채널별_비용설정'!$D$6:$D$55,"<="&B15,'3_채널별_비용설정'!$O$6:$O$55,">="&B15))) -> 4400 | N15: =IF(J15="","",IF(J15<>"정상","비용 설정 필요",SUMIFS('3_채널별_비용설정'!$M$6:$M$55,'3_채널별_비용설정'!$C$6:$C$55,C15,'3_채널별_비용설정'!$D$6:$D$55,"<="&B15,'3_채널별_비용설정'!$O$6:$O$55,">="&B15))) -> 5400 | O15: =IF(J15="","",IF(J15<>"정상","비용 설정 필요",(D15*M15)+(E15*N15))) -> 120000 | P15: =IF(J15="","",IF(J15<>"정상","비용 설정 필요",L15+O15+H15)) -> 157850 | Q15: =IF(J15="","",IF(J15<>"정상","비용 설정 필요",G15-P15)) -> -62850 | R15: =IF(J15="","",IF(J15<>"정상","비용 설정 필요",IFERROR(Q15/G15,0))) -> -0.66157895
B16: 46353 | C16: 고흥몰 | D16: 25 | E16: 12 | F16: =IF(AND(B16="",C16=""),"",SUM(D16:E16)) -> 37 | G16: 1520000 | H16: 0 | I16: [예시] 고흥몰 베스트 상품전 | J16: =IF(AND(B16="",C16=""),"",IF(OR(B16="",C16=""),"비용 설정 필요",IF(COUNTIFS('3_채널별_비용설정'!$C$6:$C$55,C16,'3_채널별_비용설정'!$D$6:$D$55,"<="&B16,'3_채널별_비용설정'!$O$6:$O$55,">="&B16)=0,"비용 설정 필요",IF(COUNTIFS('3_채널별_비용설정'!$C$6:$C$55,C16,'3_채널별_비용설정'!$D$6:$D$55,"<="&B16,'3_채널별_비용설정'!$O$6:$O$55,">="&B16)>1,"기간 중복 확인","정상")))) -> 정상 | K16: =IF(J16="","",IF(J16<>"정상","비용 설정 필요",SUMIFS('3_채널별_비용설정'!$F$6:$F$55,'3_채널별_비용설정'!$C$6:$C$55,C16,'3_채널별_비용설정'!$D$6:$D$55,"<="&B16,'3_채널별_비용설정'!$O$6:$O$55,">="&B16))) -> 0.04 | L16: =IF(J16="","",IF(J16<>"정상","비용 설정 필요",ROUND(G16*K16,0))) -> 60800 | M16: =IF(J16="","",IF(J16<>"정상","비용 설정 필요",SUMIFS('3_채널별_비용설정'!$L$6:$L$55,'3_채널별_비용설정'!$C$6:$C$55,C16,'3_채널별_비용설정'!$D$6:$D$55,"<="&B16,'3_채널별_비용설정'!$O$6:$O$55,">="&B16))) -> 3900 | N16: =IF(J16="","",IF(J16<>"정상","비용 설정 필요",SUMIFS('3_채널별_비용설정'!$M$6:$M$55,'3_채널별_비용설정'!$C$6:$C$55,C16,'3_채널별_비용설정'!$D$6:$D$55,"<="&B16,'3_채널별_비용설정'!$O$6:$O$55,">="&B16))) -> 4900 | O16: =IF(J16="","",IF(J16<>"정상","비용 설정 필요",(D16*M16)+(E16*N16))) -> 156300 | P16: =IF(J16="","",IF(J16<>"정상","비용 설정 필요",L16+O16+H16)) -> 217100 | Q16: =IF(J16="","",IF(J16<>"정상","비용 설정 필요",G16-P16)) -> 1302900 | R16: =IF(J16="","",IF(J16<>"정상","비용 설정 필요",IFERROR(Q16/G16,0))) -> 0.85717105
B17: 46355 | C17: 카톡 | D17: 20 | E17: 8 | F17: =IF(AND(B17="",C17=""),"",SUM(D17:E17)) -> 28 | G17: 1120000 | H17: 0 | I17: [예시] 월말 카톡 재구매 주문 | J17: =IF(AND(B17="",C17=""),"",IF(OR(B17="",C17=""),"비용 설정 필요",IF(COUNTIFS('3_채널별_비용설정'!$C$6:$C$55,C17,'3_채널별_비용설정'!$D$6:$D$55,"<="&B17,'3_채널별_비용설정'!$O$6:$O$55,">="&B17)=0,"비용 설정 필요",IF(COUNTIFS('3_채널별_비용설정'!$C$6:$C$55,C17,'3_채널별_비용설정'!$D$6:$D$55,"<="&B17,'3_채널별_비용설정'!$O$6:$O$55,">="&B17)>1,"기간 중복 확인","정상")))) -> 정상 | K17: =IF(J17="","",IF(J17<>"정상","비용 설정 필요",SUMIFS('3_채널별_비용설정'!$F$6:$F$55,'3_채널별_비용설정'!$C$6:$C$55,C17,'3_채널별_비용설정'!$D$6:$D$55,"<="&B17,'3_채널별_비용설정'!$O$6:$O$55,">="&B17))) -> 0.033 | L17: =IF(J17="","",IF(J17<>"정상","비용 설정 필요",ROUND(G17*K17,0))) -> 36960 | M17: =IF(J17="","",IF(J17<>"정상","비용 설정 필요",SUMIFS('3_채널별_비용설정'!$L$6:$L$55,'3_채널별_비용설정'!$C$6:$C$55,C17,'3_채널별_비용설정'!$D$6:$D$55,"<="&B17,'3_채널별_비용설정'!$O$6:$O$55,">="&B17))) -> 4400 | N17: =IF(J17="","",IF(J17<>"정상","비용 설정 필요",SUMIFS('3_채널별_비용설정'!$M$6:$M$55,'3_채널별_비용설정'!$C$6:$C$55,C17,'3_채널별_비용설정'!$D$6:$D$55,"<="&B17,'3_채널별_비용설정'!$O$6:$O$55,">="&B17))) -> 5400 | O17: =IF(J17="","",IF(J17<>"정상","비용 설정 필요",(D17*M17)+(E17*N17))) -> 131200 | P17: =IF(J17="","",IF(J17<>"정상","비용 설정 필요",L17+O17+H17)) -> 168160 | Q17: =IF(J17="","",IF(J17<>"정상","비용 설정 필요",G17-P17)) -> 951840 | R17: =IF(J17="","",IF(J17<>"정상","비용 설정 필요",IFERROR(Q17/G17,0))) -> 0.84985714
... B28: 46441 | C28: 스마트스토어 | D28: 40 | E28: 12 | F28: =IF(AND(B28="",C28=""),"",SUM(D28:E28)) -> 52 | G28: 2320000 | H28: 0 | I28: [예시] 봄맞이 사전 특가 | J28: =IF(AND(B28="",C28=""),"",IF(OR(B28="",C28=""),"비용 설정 필요",IF(COUNTIFS('3_채널별_비용설정'!$C$6:$C$55,C28,'3_채널별_비용설정'!$D$6:$D$55,"<="&B28,'3_채널별_비용설정'!$O$6:$O$55,">="&B28)=0,"비용 설정 필요",IF(COUNTIFS('3_채널별_비용설정'!$C$6:$C$55,C28,'3_채널별_비용설정'!$D$6:$D$55,"<="&B28,'3_채널별_비용설정'!$O$6:$O$55,">="&B28)>1,"기간 중복 확인","정상")))) -> 정상 | K28: =IF(J28="","",IF(J28<>"정상","비용 설정 필요",SUMIFS('3_채널별_비용설정'!$F$6:$F$55,'3_채널별_비용설정'!$C$6:$C$55,C28,'3_채널별_비용설정'!$D$6:$D$55,"<="&B28,'3_채널별_비용설정'!$O$6:$O$55,">="&B28))) -> 0.058 | L28: =IF(J28="","",IF(J28<>"정상","비용 설정 필요",ROUND(G28*K28,0))) -> 134560 | M28: =IF(J28="","",IF(J28<>"정상","비용 설정 필요",SUMIFS('3_채널별_비용설정'!$L$6:$L$55,'3_채널별_비용설정'!$C$6:$C$55,C28,'3_채널별_비용설정'!$D$6:$D$55,"<="&B28,'3_채널별_비용설정'!$O$6:$O$55,">="&B28))) -> 4500 | N28: =IF(J28="","",IF(J28<>"정상","비용 설정 필요",SUMIFS('3_채널별_비용설정'!$M$6:$M$55,'3_채널별_비용설정'!$C$6:$C$55,C28,'3_채널별_비용설정'!$D$6:$D$55,"<="&B28,'3_채널별_비용설정'!$O$6:$O$55,">="&B28))) -> 5500 | O28: =IF(J28="","",IF(J28<>"정상","비용 설정 필요",(D28*M28)+(E28*N28))) -> 246000 | P28: =IF(J28="","",IF(J28<>"정상","비용 설정 필요",L28+O28+H28)) -> 380560 | Q28: =IF(J28="","",IF(J28<>"정상","비용 설정 필요",G28-P28)) -> 1939440 | R28: =IF(J28="","",IF(J28<>"정상","비용 설정 필요",IFERROR(Q28/G28,0))) -> 0.83596552
F29: =IF(AND(B29="",C29=""),"",SUM(D29:E29)) | J29: =IF(AND(B29="",C29=""),"",IF(OR(B29="",C29=""),"비용 설정 필요",IF(COUNTIFS('3_채널별_비용설정'!$C$6:$C$55,C29,'3_채널별_비용설정'!$D$6:$D$55,"<="&B29,'3_채널별_비용설정'!$O$6:$O$55,">="&B29)=0,"비용 설정 필요",IF(COUNTIFS('3_채널별_비용설정'!$C$6:$C$55,C29,'3_채널별_비용설정'!$D$6:$D$55,"<="&B29,'3_채널별_비용설정'!$O$6:$O$55,">="&B29)>1,"기간 중복 확인","정상")))) | K29: =IF(J29="","",IF(J29<>"정상","비용 설정 필요",SUMIFS('3_채널별_비용설정'!$F$6:$F$55,'3_채널별_비용설정'!$C$6:$C$55,C29,'3_채널별_비용설정'!$D$6:$D$55,"<="&B29,'3_채널별_비용설정'!$O$6:$O$55,">="&B29))) | L29: =IF(J29="","",IF(J29<>"정상","비용 설정 필요",ROUND(G29*K29,0))) | M29: =IF(J29="","",IF(J29<>"정상","비용 설정 필요",SUMIFS('3_채널별_비용설정'!$L$6:$L$55,'3_채널별_비용설정'!$C$6:$C$55,C29,'3_채널별_비용설정'!$D$6:$D$55,"<="&B29,'3_채널별_비용설정'!$O$6:$O$55,">="&B29))) | N29: =IF(J29="","",IF(J29<>"정상","비용 설정 필요",SUMIFS('3_채널별_비용설정'!$M$6:$M$55,'3_채널별_비용설정'!$C$6:$C$55,C29,'3_채널별_비용설정'!$D$6:$D$55,"<="&B29,'3_채널별_비용설정'!$O$6:$O$55,">="&B29))) | O29: =IF(J29="","",IF(J29<>"정상","비용 설정 필요",(D29*M29)+(E29*N29))) | P29: =IF(J29="","",IF(J29<>"정상","비용 설정 필요",L29+O29+H29)) | Q29: =IF(J29="","",IF(J29<>"정상","비용 설정 필요",G29-P29)) | R29: =IF(J29="","",IF(J29<>"정상","비용 설정 필요",IFERROR(Q29/G29,0)))
F30: =IF(AND(B30="",C30=""),"",SUM(D30:E30)) | J30: =IF(AND(B30="",C30=""),"",IF(OR(B30="",C30=""),"비용 설정 필요",IF(COUNTIFS('3_채널별_비용설정'!$C$6:$C$55,C30,'3_채널별_비용설정'!$D$6:$D$55,"<="&B30,'3_채널별_비용설정'!$O$6:$O$55,">="&B30)=0,"비용 설정 필요",IF(COUNTIFS('3_채널별_비용설정'!$C$6:$C$55,C30,'3_채널별_비용설정'!$D$6:$D$55,"<="&B30,'3_채널별_비용설정'!$O$6:$O$55,">="&B30)>1,"기간 중복 확인","정상")))) | K30: =IF(J30="","",IF(J30<>"정상","비용 설정 필요",SUMIFS('3_채널별_비용설정'!$F$6:$F$55,'3_채널별_비용설정'!$C$6:$C$55,C30,'3_채널별_비용설정'!$D$6:$D$55,"<="&B30,'3_채널별_비용설정'!$O$6:$O$55,">="&B30))) | L30: =IF(J30="","",IF(J30<>"정상","비용 설정 필요",ROUND(G30*K30,0))) | M30: =IF(J30="","",IF(J30<>"정상","비용 설정 필요",SUMIFS('3_채널별_비용설정'!$L$6:$L$55,'3_채널별_비용설정'!$C$6:$C$55,C30,'3_채널별_비용설정'!$D$6:$D$55,"<="&B30,'3_채널별_비용설정'!$O$6:$O$55,">="&B30))) | N30: =IF(J30="","",IF(J30<>"정상","비용 설정 필요",SUMIFS('3_채널별_비용설정'!$M$6:$M$55,'3_채널별_비용설정'!$C$6:$C$55,C30,'3_채널별_비용설정'!$D$6:$D$55,"<="&B30,'3_채널별_비용설정'!$O$6:$O$55,">="&B30))) | O30: =IF(J30="","",IF(J30<>"정상","비용 설정 필요",(D30*M30)+(E30*N30))) | P30: =IF(J30="","",IF(J30<>"정상","비용 설정 필요",L30+O30+H30)) | Q30: =IF(J30="","",IF(J30<>"정상","비용 설정 필요",G30-P30)) | R30: =IF(J30="","",IF(J30<>"정상","비용 설정 필요",IFERROR(Q30/G30,0)))
F31: =IF(AND(B31="",C31=""),"",SUM(D31:E31)) | J31: =IF(AND(B31="",C31=""),"",IF(OR(B31="",C31=""),"비용 설정 필요",IF(COUNTIFS('3_채널별_비용설정'!$C$6:$C$55,C31,'3_채널별_비용설정'!$D$6:$D$55,"<="&B31,'3_채널별_비용설정'!$O$6:$O$55,">="&B31)=0,"비용 설정 필요",IF(COUNTIFS('3_채널별_비용설정'!$C$6:$C$55,C31,'3_채널별_비용설정'!$D$6:$D$55,"<="&B31,'3_채널별_비용설정'!$O$6:$O$55,">="&B31)>1,"기간 중복 확인","정상")))) | K31: =IF(J31="","",IF(J31<>"정상","비용 설정 필요",SUMIFS('3_채널별_비용설정'!$F$6:$F$55,'3_채널별_비용설정'!$C$6:$C$55,C31,'3_채널별_비용설정'!$D$6:$D$55,"<="&B31,'3_채널별_비용설정'!$O$6:$O$55,">="&B31))) | L31: =IF(J31="","",IF(J31<>"정상","비용 설정 필요",ROUND(G31*K31,0))) | M31: =IF(J31="","",IF(J31<>"정상","비용 설정 필요",SUMIFS('3_채널별_비용설정'!$L$6:$L$55,'3_채널별_비용설정'!$C$6:$C$55,C31,'3_채널별_비용설정'!$D$6:$D$55,"<="&B31,'3_채널별_비용설정'!$O$6:$O$55,">="&B31))) | N31: =IF(J31="","",IF(J31<>"정상","비용 설정 필요",SUMIFS('3_채널별_비용설정'!$M$6:$M$55,'3_채널별_비용설정'!$C$6:$C$55,C31,'3_채널별_비용설정'!$D$6:$D$55,"<="&B31,'3_채널별_비용설정'!$O$6:$O$55,">="&B31))) | O31: =IF(J31="","",IF(J31<>"정상","비용 설정 필요",(D31*M31)+(E31*N31))) | P31: =IF(J31="","",IF(J31<>"정상","비용 설정 필요",L31+O31+H31)) | Q31: =IF(J31="","",IF(J31<>"정상","비용 설정 필요",G31-P31)) | R31: =IF(J31="","",IF(J31<>"정상","비용 설정 필요",IFERROR(Q31/G31,0)))
F32: =IF(AND(B32="",C32=""),"",SUM(D32:E32)) | J32: =IF(AND(B32="",C32=""),"",IF(OR(B32="",C32=""),"비용 설정 필요",IF(COUNTIFS('3_채널별_비용설정'!$C$6:$C$55,C32,'3_채널별_비용설정'!$D$6:$D$55,"<="&B32,'3_채널별_비용설정'!$O$6:$O$55,">="&B32)=0,"비용 설정 필요",IF(COUNTIFS('3_채널별_비용설정'!$C$6:$C$55,C32,'3_채널별_비용설정'!$D$6:$D$55,"<="&B32,'3_채널별_비용설정'!$O$6:$O$55,">="&B32)>1,"기간 중복 확인","정상")))) | K32: =IF(J32="","",IF(J32<>"정상","비용 설정 필요",SUMIFS('3_채널별_비용설정'!$F$6:$F$55,'3_채널별_비용설정'!$C$6:$C$55,C32,'3_채널별_비용설정'!$D$6:$D$55,"<="&B32,'3_채널별_비용설정'!$O$6:$O$55,">="&B32))) | L32: =IF(J32="","",IF(J32<>"정상","비용 설정 필요",ROUND(G32*K32,0))) | M32: =IF(J32="","",IF(J32<>"정상","비용 설정 필요",SUMIFS('3_채널별_비용설정'!$L$6:$L$55,'3_채널별_비용설정'!$C$6:$C$55,C32,'3_채널별_비용설정'!$D$6:$D$55,"<="&B32,'3_채널별_비용설정'!$O$6:$O$55,">="&B32))) | N32: =IF(J32="","",IF(J32<>"정상","비용 설정 필요",SUMIFS('3_채널별_비용설정'!$M$6:$M$55,'3_채널별_비용설정'!$C$6:$C$55,C32,'3_채널별_비용설정'!$D$6:$D$55,"<="&B32,'3_채널별_비용설정'!$O$6:$O$55,">="&B32))) | O32: =IF(J32="","",IF(J32<>"정상","비용 설정 필요",(D32*M32)+(E32*N32))) | P32: =IF(J32="","",IF(J32<>"정상","비용 설정 필요",L32+O32+H32)) | Q32: =IF(J32="","",IF(J32<>"정상","비용 설정 필요",G32-P32)) | R32: =IF(J32="","",IF(J32<>"정상","비용 설정 필요",IFERROR(Q32/G32,0)))
F33: =IF(AND(B33="",C33=""),"",SUM(D33:E33)) | J33: =IF(AND(B33="",C33=""),"",IF(OR(B33="",C33=""),"비용 설정 필요",IF(COUNTIFS('3_채널별_비용설정'!$C$6:$C$55,C33,'3_채널별_비용설정'!$D$6:$D$55,"<="&B33,'3_채널별_비용설정'!$O$6:$O$55,">="&B33)=0,"비용 설정 필요",IF(COUNTIFS('3_채널별_비용설정'!$C$6:$C$55,C33,'3_채널별_비용설정'!$D$6:$D$55,"<="&B33,'3_채널별_비용설정'!$O$6:$O$55,">="&B33)>1,"기간 중복 확인","정상")))) | K33: =IF(J33="","",IF(J33<>"정상","비용 설정 필요",SUMIFS('3_채널별_비용설정'!$F$6:$F$55,'3_채널별_비용설정'!$C$6:$C$55,C33,'3_채널별_비용설정'!$D$6:$D$55,"<="&B33,'3_채널별_비용설정'!$O$6:$O$55,">="&B33))) | L33: =IF(J33="","",IF(J33<>"정상","비용 설정 필요",ROUND(G33*K33,0))) | M33: =IF(J33="","",IF(J33<>"정상","비용 설정 필요",SUMIFS('3_채널별_비용설정'!$L$6:$L$55,'3_채널별_비용설정'!$C$6:$C$55,C33,'3_채널별_비용설정'!$D$6:$D$55,"<="&B33,'3_채널별_비용설정'!$O$6:$O$55,">="&B33))) | N33: =IF(J33="","",IF(J33<>"정상","비용 설정 필요",SUMIFS('3_채널별_비용설정'!$M$6:$M$55,'3_채널별_비용설정'!$C$6:$C$55,C33,'3_채널별_비용설정'!$D$6:$D$55,"<="&B33,'3_채널별_비용설정'!$O$6:$O$55,">="&B33))) | O33: =IF(J33="","",IF(J33<>"정상","비용 설정 필요",(D33*M33)+(E33*N33))) | P33: =IF(J33="","",IF(J33<>"정상","비용 설정 필요",L33+O33+H33)) | Q33: =IF(J33="","",IF(J33<>"정상","비용 설정 필요",G33-P33)) | R33: =IF(J33="","",IF(J33<>"정상","비용 설정 필요",IFERROR(Q33/G33,0)))
F34: =IF(AND(B34="",C34=""),"",SUM(D34:E34)) | J34: =IF(AND(B34="",C34=""),"",IF(OR(B34="",C34=""),"비용 설정 필요",IF(COUNTIFS('3_채널별_비용설정'!$C$6:$C$55,C34,'3_채널별_비용설정'!$D$6:$D$55,"<="&B34,'3_채널별_비용설정'!$O$6:$O$55,">="&B34)=0,"비용 설정 필요",IF(COUNTIFS('3_채널별_비용설정'!$C$6:$C$55,C34,'3_채널별_비용설정'!$D$6:$D$55,"<="&B34,'3_채널별_비용설정'!$O$6:$O$55,">="&B34)>1,"기간 중복 확인","정상")))) | K34: =IF(J34="","",IF(J34<>"정상","비용 설정 필요",SUMIFS('3_채널별_비용설정'!$F$6:$F$55,'3_채널별_비용설정'!$C$6:$C$55,C34,'3_채널별_비용설정'!$D$6:$D$55,"<="&B34,'3_채널별_비용설정'!$O$6:$O$55,">="&B34))) | L34: =IF(J34="","",IF(J34<>"정상","비용 설정 필요",ROUND(G34*K34,0))) | M34: =IF(J34="","",IF(J34<>"정상","비용 설정 필요",SUMIFS('3_채널별_비용설정'!$L$6:$L$55,'3_채널별_비용설정'!$C$6:$C$55,C34,'3_채널별_비용설정'!$D$6:$D$55,"<="&B34,'3_채널별_비용설정'!$O$6:$O$55,">="&B34))) | N34: =IF(J34="","",IF(J34<>"정상","비용 설정 필요",SUMIFS('3_채널별_비용설정'!$M$6:$M$55,'3_채널별_비용설정'!$C$6:$C$55,C34,'3_채널별_비용설정'!$D$6:$D$55,"<="&B34,'3_채널별_비용설정'!$O$6:$O$55,">="&B34))) | O34: =IF(J34="","",IF(J34<>"정상","비용 설정 필요",(D34*M34)+(E34*N34))) | P34: =IF(J34="","",IF(J34<>"정상","비용 설정 필요",L34+O34+H34)) | Q34: =IF(J34="","",IF(J34<>"정상","비용 설정 필요",G34-P34)) | R34: =IF(J34="","",IF(J34<>"정상","비용 설정 필요",IFERROR(Q34/G34,0)))
F35: =IF(AND(B35="",C35=""),"",SUM(D35:E35)) | J35: =IF(AND(B35="",C35=""),"",IF(OR(B35="",C35=""),"비용 설정 필요",IF(COUNTIFS('3_채널별_비용설정'!$C$6:$C$55,C35,'3_채널별_비용설정'!$D$6:$D$55,"<="&B35,'3_채널별_비용설정'!$O$6:$O$55,">="&B35)=0,"비용 설정 필요",IF(COUNTIFS('3_채널별_비용설정'!$C$6:$C$55,C35,'3_채널별_비용설정'!$D$6:$D$55,"<="&B35,'3_채널별_비용설정'!$O$6:$O$55,">="&B35)>1,"기간 중복 확인","정상")))) | K35: =IF(J35="","",IF(J35<>"정상","비용 설정 필요",SUMIFS('3_채널별_비용설정'!$F$6:$F$55,'3_채널별_비용설정'!$C$6:$C$55,C35,'3_채널별_비용설정'!$D$6:$D$55,"<="&B35,'3_채널별_비용설정'!$O$6:$O$55,">="&B35))) | L35: =IF(J35="","",IF(J35<>"정상","비용 설정 필요",ROUND(G35*K35,0))) | M35: =IF(J35="","",IF(J35<>"정상","비용 설정 필요",SUMIFS('3_채널별_비용설정'!$L$6:$L$55,'3_채널별_비용설정'!$C$6:$C$55,C35,'3_채널별_비용설정'!$D$6:$D$55,"<="&B35,'3_채널별_비용설정'!$O$6:$O$55,">="&B35))) | N35: =IF(J35="","",IF(J35<>"정상","비용 설정 필요",SUMIFS('3_채널별_비용설정'!$M$6:$M$55,'3_채널별_비용설정'!$C$6:$C$55,C35,'3_채널별_비용설정'!$D$6:$D$55,"<="&B35,'3_채널별_비용설정'!$O$6:$O$55,">="&B35))) | O35: =IF(J35="","",IF(J35<>"정상","비용 설정 필요",(D35*M35)+(E35*N35))) | P35: =IF(J35="","",IF(J35<>"정상","비용 설정 필요",L35+O35+H35)) | Q35: =IF(J35="","",IF(J35<>"정상","비용 설정 필요",G35-P35)) | R35: =IF(J35="","",IF(J35<>"정상","비용 설정 필요",IFERROR(Q35/G35,0)))
F36: =IF(AND(B36="",C36=""),"",SUM(D36:E36)) | J36: =IF(AND(B36="",C36=""),"",IF(OR(B36="",C36=""),"비용 설정 필요",IF(COUNTIFS('3_채널별_비용설정'!$C$6:$C$55,C36,'3_채널별_비용설정'!$D$6:$D$55,"<="&B36,'3_채널별_비용설정'!$O$6:$O$55,">="&B36)=0,"비용 설정 필요",IF(COUNTIFS('3_채널별_비용설정'!$C$6:$C$55,C36,'3_채널별_비용설정'!$D$6:$D$55,"<="&B36,'3_채널별_비용설정'!$O$6:$O$55,">="&B36)>1,"기간 중복 확인","정상")))) | K36: =IF(J36="","",IF(J36<>"정상","비용 설정 필요",SUMIFS('3_채널별_비용설정'!$F$6:$F$55,'3_채널별_비용설정'!$C$6:$C$55,C36,'3_채널별_비용설정'!$D$6:$D$55,"<="&B36,'3_채널별_비용설정'!$O$6:$O$55,">="&B36))) | L36: =IF(J36="","",IF(J36<>"정상","비용 설정 필요",ROUND(G36*K36,0))) | M36: =IF(J36="","",IF(J36<>"정상","비용 설정 필요",SUMIFS('3_채널별_비용설정'!$L$6:$L$55,'3_채널별_비용설정'!$C$6:$C$55,C36,'3_채널별_비용설정'!$D$6:$D$55,"<="&B36,'3_채널별_비용설정'!$O$6:$O$55,">="&B36))) | N36: =IF(J36="","",IF(J36<>"정상","비용 설정 필요",SUMIFS('3_채널별_비용설정'!$M$6:$M$55,'3_채널별_비용설정'!$C$6:$C$55,C36,'3_채널별_비용설정'!$D$6:$D$55,"<="&B36,'3_채널별_비용설정'!$O$6:$O$55,">="&B36))) | O36: =IF(J36="","",IF(J36<>"정상","비용 설정 필요",(D36*M36)+(E36*N36))) | P36: =IF(J36="","",IF(J36<>"정상","비용 설정 필요",L36+O36+H36)) | Q36: =IF(J36="","",IF(J36<>"정상","비용 설정 필요",G36-P36)) | R36: =IF(J36="","",IF(J36<>"정상","비용 설정 필요",IFERROR(Q36/G36,0)))
F37: =IF(AND(B37="",C37=""),"",SUM(D37:E37)) | J37: =IF(AND(B37="",C37=""),"",IF(OR(B37="",C37=""),"비용 설정 필요",IF(COUNTIFS('3_채널별_비용설정'!$C$6:$C$55,C37,'3_채널별_비용설정'!$D$6:$D$55,"<="&B37,'3_채널별_비용설정'!$O$6:$O$55,">="&B37)=0,"비용 설정 필요",IF(COUNTIFS('3_채널별_비용설정'!$C$6:$C$55,C37,'3_채널별_비용설정'!$D$6:$D$55,"<="&B37,'3_채널별_비용설정'!$O$6:$O$55,">="&B37)>1,"기간 중복 확인","정상")))) | K37: =IF(J37="","",IF(J37<>"정상","비용 설정 필요",SUMIFS('3_채널별_비용설정'!$F$6:$F$55,'3_채널별_비용설정'!$C$6:$C$55,C37,'3_채널별_비용설정'!$D$6:$D$55,"<="&B37,'3_채널별_비용설정'!$O$6:$O$55,">="&B37))) | L37: =IF(J37="","",IF(J37<>"정상","비용 설정 필요",ROUND(G37*K37,0))) | M37: =IF(J37="","",IF(J37<>"정상","비용 설정 필요",SUMIFS('3_채널별_비용설정'!$L$6:$L$55,'3_채널별_비용설정'!$C$6:$C$55,C37,'3_채널별_비용설정'!$D$6:$D$55,"<="&B37,'3_채널별_비용설정'!$O$6:$O$55,">="&B37))) | N37: =IF(J37="","",IF(J37<>"정상","비용 설정 필요",SUMIFS('3_채널별_비용설정'!$M$6:$M$55,'3_채널별_비용설정'!$C$6:$C$55,C37,'3_채널별_비용설정'!$D$6:$D$55,"<="&B37,'3_채널별_비용설정'!$O$6:$O$55,">="&B37))) | O37: =IF(J37="","",IF(J37<>"정상","비용 설정 필요",(D37*M37)+(E37*N37))) | P37: =IF(J37="","",IF(J37<>"정상","비용 설정 필요",L37+O37+H37)) | Q37: =IF(J37="","",IF(J37<>"정상","비용 설정 필요",G37-P37)) | R37: =IF(J37="","",IF(J37<>"정상","비용 설정 필요",IFERROR(Q37/G37,0)))
F38: =IF(AND(B38="",C38=""),"",SUM(D38:E38)) | J38: =IF(AND(B38="",C38=""),"",IF(OR(B38="",C38=""),"비용 설정 필요",IF(COUNTIFS('3_채널별_비용설정'!$C$6:$C$55,C38,'3_채널별_비용설정'!$D$6:$D$55,"<="&B38,'3_채널별_비용설정'!$O$6:$O$55,">="&B38)=0,"비용 설정 필요",IF(COUNTIFS('3_채널별_비용설정'!$C$6:$C$55,C38,'3_채널별_비용설정'!$D$6:$D$55,"<="&B38,'3_채널별_비용설정'!$O$6:$O$55,">="&B38)>1,"기간 중복 확인","정상")))) | K38: =IF(J38="","",IF(J38<>"정상","비용 설정 필요",SUMIFS('3_채널별_비용설정'!$F$6:$F$55,'3_채널별_비용설정'!$C$6:$C$55,C38,'3_채널별_비용설정'!$D$6:$D$55,"<="&B38,'3_채널별_비용설정'!$O$6:$O$55,">="&B38))) | L38: =IF(J38="","",IF(J38<>"정상","비용 설정 필요",ROUND(G38*K38,0))) | M38: =IF(J38="","",IF(J38<>"정상","비용 설정 필요",SUMIFS('3_채널별_비용설정'!$L$6:$L$55,'3_채널별_비용설정'!$C$6:$C$55,C38,'3_채널별_비용설정'!$D$6:$D$55,"<="&B38,'3_채널별_비용설정'!$O$6:$O$55,">="&B38))) | N38: =IF(J38="","",IF(J38<>"정상","비용 설정 필요",SUMIFS('3_채널별_비용설정'!$M$6:$M$55,'3_채널별_비용설정'!$C$6:$C$55,C38,'3_채널별_비용설정'!$D$6:$D$55,"<="&B38,'3_채널별_비용설정'!$O$6:$O$55,">="&B38))) | O38: =IF(J38="","",IF(J38<>"정상","비용 설정 필요",(D38*M38)+(E38*N38))) | P38: =IF(J38="","",IF(J38<>"정상","비용 설정 필요",L38+O38+H38)) | Q38: =IF(J38="","",IF(J38<>"정상","비용 설정 필요",G38-P38)) | R38: =IF(J38="","",IF(J38<>"정상","비용 설정 필요",IFERROR(Q38/G38,0)))
F39: =IF(AND(B39="",C39=""),"",SUM(D39:E39)) | J39: =IF(AND(B39="",C39=""),"",IF(OR(B39="",C39=""),"비용 설정 필요",IF(COUNTIFS('3_채널별_비용설정'!$C$6:$C$55,C39,'3_채널별_비용설정'!$D$6:$D$55,"<="&B39,'3_채널별_비용설정'!$O$6:$O$55,">="&B39)=0,"비용 설정 필요",IF(COUNTIFS('3_채널별_비용설정'!$C$6:$C$55,C39,'3_채널별_비용설정'!$D$6:$D$55,"<="&B39,'3_채널별_비용설정'!$O$6:$O$55,">="&B39)>1,"기간 중복 확인","정상")))) | K39: =IF(J39="","",IF(J39<>"정상","비용 설정 필요",SUMIFS('3_채널별_비용설정'!$F$6:$F$55,'3_채널별_비용설정'!$C$6:$C$55,C39,'3_채널별_비용설정'!$D$6:$D$55,"<="&B39,'3_채널별_비용설정'!$O$6:$O$55,">="&B39))) | L39: =IF(J39="","",IF(J39<>"정상","비용 설정 필요",ROUND(G39*K39,0))) | M39: =IF(J39="","",IF(J39<>"정상","비용 설정 필요",SUMIFS('3_채널별_비용설정'!$L$6:$L$55,'3_채널별_비용설정'!$C$6:$C$55,C39,'3_채널별_비용설정'!$D$6:$D$55,"<="&B39,'3_채널별_비용설정'!$O$6:$O$55,">="&B39))) | N39: =IF(J39="","",IF(J39<>"정상","비용 설정 필요",SUMIFS('3_채널별_비용설정'!$M$6:$M$55,'3_채널별_비용설정'!$C$6:$C$55,C39,'3_채널별_비용설정'!$D$6:$D$55,"<="&B39,'3_채널별_비용설정'!$O$6:$O$55,">="&B39))) | O39: =IF(J39="","",IF(J39<>"정상","비용 설정 필요",(D39*M39)+(E39*N39))) | P39: =IF(J39="","",IF(J39<>"정상","비용 설정 필요",L39+O39+H39)) | Q39: =IF(J39="","",IF(J39<>"정상","비용 설정 필요",G39-P39)) | R39: =IF(J39="","",IF(J39<>"정상","비용 설정 필요",IFERROR(Q39/G39,0)))
F40: =IF(AND(B40="",C40=""),"",SUM(D40:E40)) | J40: =IF(AND(B40="",C40=""),"",IF(OR(B40="",C40=""),"비용 설정 필요",IF(COUNTIFS('3_채널별_비용설정'!$C$6:$C$55,C40,'3_채널별_비용설정'!$D$6:$D$55,"<="&B40,'3_채널별_비용설정'!$O$6:$O$55,">="&B40)=0,"비용 설정 필요",IF(COUNTIFS('3_채널별_비용설정'!$C$6:$C$55,C40,'3_채널별_비용설정'!$D$6:$D$55,"<="&B40,'3_채널별_비용설정'!$O$6:$O$55,">="&B40)>1,"기간 중복 확인","정상")))) | K40: =IF(J40="","",IF(J40<>"정상","비용 설정 필요",SUMIFS('3_채널별_비용설정'!$F$6:$F$55,'3_채널별_비용설정'!$C$6:$C$55,C40,'3_채널별_비용설정'!$D$6:$D$55,"<="&B40,'3_채널별_비용설정'!$O$6:$O$55,">="&B40))) | L40: =IF(J40="","",IF(J40<>"정상","비용 설정 필요",ROUND(G40*K40,0))) | M40: =IF(J40="","",IF(J40<>"정상","비용 설정 필요",SUMIFS('3_채널별_비용설정'!$L$6:$L$55,'3_채널별_비용설정'!$C$6:$C$55,C40,'3_채널별_비용설정'!$D$6:$D$55,"<="&B40,'3_채널별_비용설정'!$O$6:$O$55,">="&B40))) | N40: =IF(J40="","",IF(J40<>"정상","비용 설정 필요",SUMIFS('3_채널별_비용설정'!$M$6:$M$55,'3_채널별_비용설정'!$C$6:$C$55,C40,'3_채널별_비용설정'!$D$6:$D$55,"<="&B40,'3_채널별_비용설정'!$O$6:$O$55,">="&B40))) | O40: =IF(J40="","",IF(J40<>"정상","비용 설정 필요",(D40*M40)+(E40*N40))) | P40: =IF(J40="","",IF(J40<>"정상","비용 설정 필요",L40+O40+H40)) | Q40: =IF(J40="","",IF(J40<>"정상","비용 설정 필요",G40-P40)) | R40: =IF(J40="","",IF(J40<>"정상","비용 설정 필요",IFERROR(Q40/G40,0)))
... F305: =IF(AND(B305="",C305=""),"",SUM(D305:E305)) | J305: =IF(AND(B305="",C305=""),"",IF(OR(B305="",C305=""),"비용 설정 필요",IF(COUNTIFS('3_채널별_비용설정'!$C$6:$C$55,C305,'3_채널별_비용설정'!$D$6:$D$55,"<="&B305,'3_채널별_비용설정'!$O$6:$O$55,">="&B305)=0,"비용 설정 필요",IF(COUNTIFS('3_채널별_비용설정'!$C$6:$C$55,C305,'3_채널별_비용설정'!$D$6:$D$55,"<="&B305,'3_채널별_비용설정'!$O$6:$O$55,">="&B305)>1,"기간 중복 확인","정상")))) | K305: =IF(J305="","",IF(J305<>"정상","비용 설정 필요",SUMIFS('3_채널별_비용설정'!$F$6:$F$55,'3_채널별_비용설정'!$C$6:$C$55,C305,'3_채널별_비용설정'!$D$6:$D$55,"<="&B305,'3_채널별_비용설정'!$O$6:$O$55,">="&B305))) | L305: =IF(J305="","",IF(J305<>"정상","비용 설정 필요",ROUND(G305*K305,0))) | M305: =IF(J305="","",IF(J305<>"정상","비용 설정 필요",SUMIFS('3_채널별_비용설정'!$L$6:$L$55,'3_채널별_비용설정'!$C$6:$C$55,C305,'3_채널별_비용설정'!$D$6:$D$55,"<="&B305,'3_채널별_비용설정'!$O$6:$O$55,">="&B305))) | N305: =IF(J305="","",IF(J305<>"정상","비용 설정 필요",SUMIFS('3_채널별_비용설정'!$M$6:$M$55,'3_채널별_비용설정'!$C$6:$C$55,C305,'3_채널별_비용설정'!$D$6:$D$55,"<="&B305,'3_채널별_비용설정'!$O$6:$O$55,">="&B305))) | O305: =IF(J305="","",IF(J305<>"정상","비용 설정 필요",(D305*M305)+(E305*N305))) | P305: =IF(J305="","",IF(J305<>"정상","비용 설정 필요",L305+O305+H305)) | Q305: =IF(J305="","",IF(J305<>"정상","비용 설정 필요",G305-P305)) | R305: =IF(J305="","",IF(J305<>"정상","비용 설정 필요",IFERROR(Q305/G305,0)))

Sheet 3_채널별_비용설정
B2: 매출·지출관리 스프레드시트(순이익/실적 자동계산) | 판매채널·기간별 비용 설정
B3: 💡 [비용 설정 안내] ① 주문 무게에 따라 [10kg 미만 배송비]와 [10kg 이상 배송비]를 구분하여 설정하고, 주문 1건당 [박스 비용], [포장비닐 비용], [리플렛 비용]을 입력하세요. ② 비용이 변경되면 기존 설정의 [적용 종료일]을 입력하고 아래 새 행에 [새로운 적용 시작일]로 추가하세요. (웹 화면에서는 달력 아이콘 클릭으로 날짜를 바로 선택할 수 있습니다.)
B5: No | C5: 판매채널 (드롭다운) | D5: 적용 시작일 (달력/날짜선택) | E5: 적용 종료일 (비워두면 계속) | F5: 매출액 기준 수수료율 (%) | G5: 10kg 미만 배송비 (원) | H5: 10kg 이상 배송비 (원) | I5: 박스 비용 (1건당, 원) | J5: 포장비닐 비용 (1건당, 원) | K5: 리플렛 비용 (1건당, 원) | L5: 10kg 미만 1건당 합계(자동) | M5: 10kg 이상 1건당 합계(자동) | N5: 적용 기간 중복/오류 검증 | O5: 종료 기준일 (수식 자동처리) | P5: 비고 (단가 변경 이력 및 메모)
B6: =IF(C6="","",ROW()-5) -> 1 | C6: 농라 | D6: 46327 | F6: 0 | G6: 3500 | H6: 4500 | I6: 650 | J6: 150 | K6: 100 | L6: =IF(C6="","",G6+SUM(I6:K6)) -> 4400 | M6: =IF(C6="","",H6+SUM(I6:K6)) -> 5400 | N6: =IF(C6="","",IF(D6>O6,"⚠️ 시작일>종료일 오류",IF(COUNTIFS($C$6:$C$55,C6,$D$6:$D$55,"<="&O6,$O$6:$O$55,">="&D6)>1,"⚠️ 기간 중복","정상"))) -> 정상 | O6: =IF(C6="","",IF(E6="",DATE(2099,12,31),E6)) -> 73050 | P6: [예시] 농라 카페 직거래 (수수료 0%, 10kg미만 3,500원 / 10kg이상 4,500원)
B7: =IF(C7="","",ROW()-5) -> 2 | C7: 스마트스토어 | D7: 46327 | E7: 46341 | F7: 0.055 | G7: 3200 | H7: 4200 | I7: 650 | J7: 150 | K7: 100 | L7: =IF(C7="","",G7+SUM(I7:K7)) -> 4100 | M7: =IF(C7="","",H7+SUM(I7:K7)) -> 5100 | N7: =IF(C7="","",IF(D7>O7,"⚠️ 시작일>종료일 오류",IF(COUNTIFS($C$6:$C$55,C7,$D$6:$D$55,"<="&O7,$O$6:$O$55,">="&D7)>1,"⚠️ 기간 중복","정상"))) -> 정상 | O7: =IF(C7="","",IF(E7="",DATE(2099,12,31),E7)) -> 46341 | P7: [단가변경 전] 11/15까지 적용 단가 (수수료 5.5%, 미만택배 3,200원/이상 4,200원)
B8: =IF(C8="","",ROW()-5) -> 3 | C8: 스마트스토어 | D8: 46342 | F8: 0.058 | G8: 3500 | H8: 4500 | I8: 750 | J8: 150 | K8: 100 | L8: =IF(C8="","",G8+SUM(I8:K8)) -> 4500 | M8: =IF(C8="","",H8+SUM(I8:K8)) -> 5500 | N8: =IF(C8="","",IF(D8>O8,"⚠️ 시작일>종료일 오류",IF(COUNTIFS($C$6:$C$55,C8,$D$6:$D$55,"<="&O8,$O$6:$O$55,">="&D8)>1,"⚠️ 기간 중복","정상"))) -> 정상 | O8: =IF(C8="","",IF(E8="",DATE(2099,12,31),E8)) -> 73050 | P8: [단가변경 후] 11/16부터 택배비·박스비 인상 적용 (과거 매출은 이전 단가 유지)
B9: =IF(C9="","",ROW()-5) -> 4 | C9: 카톡 | D9: 46327 | F9: 0.033 | G9: 3500 | H9: 4500 | I9: 650 | J9: 150 | K9: 100 | L9: =IF(C9="","",G9+SUM(I9:K9)) -> 4400 | M9: =IF(C9="","",H9+SUM(I9:K9)) -> 5400 | N9: =IF(C9="","",IF(D9>O9,"⚠️ 시작일>종료일 오류",IF(COUNTIFS($C$6:$C$55,C9,$D$6:$D$55,"<="&O9,$O$6:$O$55,">="&D9)>1,"⚠️ 기간 중복","정상"))) -> 정상 | O9: =IF(C9="","",IF(E9="",DATE(2099,12,31),E9)) -> 73050 | P9: [예시] 카카오톡 톡채널/선물 주문
B10: =IF(C10="","",ROW()-5) -> 5 | C10: 고흥몰 | D10: 46327 | F10: 0.04 | G10: 3000 | H10: 4000 | I10: 650 | J10: 150 | K10: 100 | L10: =IF(C10="","",G10+SUM(I10:K10)) -> 3900 | M10: =IF(C10="","",H10+SUM(I10:K10)) -> 4900 | N10: =IF(C10="","",IF(D10>O10,"⚠️ 시작일>종료일 오류",IF(COUNTIFS($C$6:$C$55,C10,$D$6:$D$55,"<="&O10,$O$6:$O$55,">="&D10)>1,"⚠️ 기간 중복","정상"))) -> 정상 | O10: =IF(C10="","",IF(E10="",DATE(2099,12,31),E10)) -> 73050 | P10: [예시] 고흥몰 입점 특산물 판매
B11: =IF(C11="","",ROW()-5) -> 6 | C11: 남도장터 | D11: 46327 | F11: 0.05 | G11: 3200 | H11: 4200 | I11: 650 | J11: 150 | K11: 100 | L11: =IF(C11="","",G11+SUM(I11:K11)) -> 4100 | M11: =IF(C11="","",H11+SUM(I11:K11)) -> 5100 | N11: =IF(C11="","",IF(D11>O11,"⚠️ 시작일>종료일 오류",IF(COUNTIFS($C$6:$C$55,C11,$D$6:$D$55,"<="&O11,$O$6:$O$55,">="&D11)>1,"⚠️ 기간 중복","정상"))) -> 정상 | O11: =IF(C11="","",IF(E11="",DATE(2099,12,31),E11)) -> 73050 | P11: [예시] 남도장터 온라인몰 판매
B12: =IF(C12="","",ROW()-5) -> 7 | C12: 로컬푸드 | D12: 46327 | F12: 0.1 | G12: 0 | H12: 0 | I12: 400 | J12: 120 | K12: 80 | L12: =IF(C12="","",G12+SUM(I12:K12)) -> 600 | M12: =IF(C12="","",H12+SUM(I12:K12)) -> 600 | N12: =IF(C12="","",IF(D12>O12,"⚠️ 시작일>종료일 오류",IF(COUNTIFS($C$6:$C$55,C12,$D$6:$D$55,"<="&O12,$O$6:$O$55,">="&D12)>1,"⚠️ 기간 중복","정상"))) -> 정상 | O12: =IF(C12="","",IF(E12="",DATE(2099,12,31),E12)) -> 73050 | P12: [예시] 로컬푸드 직매장 납품 (택배비 없음, 소포장 박스·비닐·리플렛만 적용)
B13: =IF(C13="","",ROW()-5) -> 8 | C13: 기타 | D13: 46327 | F13: 0.03 | G13: 3500 | H13: 4500 | I13: 650 | J13: 150 | K13: 100 | L13: =IF(C13="","",G13+SUM(I13:K13)) -> 4400 | M13: =IF(C13="","",H13+SUM(I13:K13)) -> 5400 | N13: =IF(C13="","",IF(D13>O13,"⚠️ 시작일>종료일 오류",IF(COUNTIFS($C$6:$C$55,C13,$D$6:$D$55,"<="&O13,$O$6:$O$55,">="&D13)>1,"⚠️ 기간 중복","정상"))) -> 정상 | O13: =IF(C13="","",IF(E13="",DATE(2099,12,31),E13)) -> 73050 | P13: [예시] 전화/방문 및 기타 외부채널 기본값
B14: =IF(C14="","",ROW()-5) | L14: =IF(C14="","",G14+SUM(I14:K14)) | M14: =IF(C14="","",H14+SUM(I14:K14)) | N14: =IF(C14="","",IF(D14>O14,"⚠️ 시작일>종료일 오류",IF(COUNTIFS($C$6:$C$55,C14,$D$6:$D$55,"<="&O14,$O$6:$O$55,">="&D14)>1,"⚠️ 기간 중복","정상"))) | O14: =IF(C14="","",IF(E14="",DATE(2099,12,31),E14))
B15: =IF(C15="","",ROW()-5) | L15: =IF(C15="","",G15+SUM(I15:K15)) | M15: =IF(C15="","",H15+SUM(I15:K15)) | N15: =IF(C15="","",IF(D15>O15,"⚠️ 시작일>종료일 오류",IF(COUNTIFS($C$6:$C$55,C15,$D$6:$D$55,"<="&O15,$O$6:$O$55,">="&D15)>1,"⚠️ 기간 중복","정상"))) | O15: =IF(C15="","",IF(E15="",DATE(2099,12,31),E15))
B16: =IF(C16="","",ROW()-5) | L16: =IF(C16="","",G16+SUM(I16:K16)) | M16: =IF(C16="","",H16+SUM(I16:K16)) | N16: =IF(C16="","",IF(D16>O16,"⚠️ 시작일>종료일 오류",IF(COUNTIFS($C$6:$C$55,C16,$D$6:$D$55,"<="&O16,$O$6:$O$55,">="&D16)>1,"⚠️ 기간 중복","정상"))) | O16: =IF(C16="","",IF(E16="",DATE(2099,12,31),E16))
B17: =IF(C17="","",ROW()-5) | L17: =IF(C17="","",G17+SUM(I17:K17)) | M17: =IF(C17="","",H17+SUM(I17:K17)) | N17: =IF(C17="","",IF(D17>O17,"⚠️ 시작일>종료일 오류",IF(COUNTIFS($C$6:$C$55,C17,$D$6:$D$55,"<="&O17,$O$6:$O$55,">="&D17)>1,"⚠️ 기간 중복","정상"))) | O17: =IF(C17="","",IF(E17="",DATE(2099,12,31),E17))
B18: =IF(C18="","",ROW()-5) | L18: =IF(C18="","",G18+SUM(I18:K18)) | M18: =IF(C18="","",H18+SUM(I18:K18)) | N18: =IF(C18="","",IF(D18>O18,"⚠️ 시작일>종료일 오류",IF(COUNTIFS($C$6:$C$55,C18,$D$6:$D$55,"<="&O18,$O$6:$O$55,">="&D18)>1,"⚠️ 기간 중복","정상"))) | O18: =IF(C18="","",IF(E18="",DATE(2099,12,31),E18))
B19: =IF(C19="","",ROW()-5) | L19: =IF(C19="","",G19+SUM(I19:K19)) | M19: =IF(C19="","",H19+SUM(I19:K19)) | N19: =IF(C19="","",IF(D19>O19,"⚠️ 시작일>종료일 오류",IF(COUNTIFS($C$6:$C$55,C19,$D$6:$D$55,"<="&O19,$O$6:$O$55,">="&D19)>1,"⚠️ 기간 중복","정상"))) | O19: =IF(C19="","",IF(E19="",DATE(2099,12,31),E19))
B20: =IF(C20="","",ROW()-5) | L20: =IF(C20="","",G20+SUM(I20:K20)) | M20: =IF(C20="","",H20+SUM(I20:K20)) | N20: =IF(C20="","",IF(D20>O20,"⚠️ 시작일>종료일 오류",IF(COUNTIFS($C$6:$C$55,C20,$D$6:$D$55,"<="&O20,$O$6:$O$55,">="&D20)>1,"⚠️ 기간 중복","정상"))) | O20: =IF(C20="","",IF(E20="",DATE(2099,12,31),E20))
B21: =IF(C21="","",ROW()-5) | L21: =IF(C21="","",G21+SUM(I21:K21)) | M21: =IF(C21="","",H21+SUM(I21:K21)) | N21: =IF(C21="","",IF(D21>O21,"⚠️ 시작일>종료일 오류",IF(COUNTIFS($C$6:$C$55,C21,$D$6:$D$55,"<="&O21,$O$6:$O$55,">="&D21)>1,"⚠️ 기간 중복","정상"))) | O21: =IF(C21="","",IF(E21="",DATE(2099,12,31),E21))
B22: =IF(C22="","",ROW()-5) | L22: =IF(C22="","",G22+SUM(I22:K22)) | M22: =IF(C22="","",H22+SUM(I22:K22)) | N22: =IF(C22="","",IF(D22>O22,"⚠️ 시작일>종료일 오류",IF(COUNTIFS($C$6:$C$55,C22,$D$6:$D$55,"<="&O22,$O$6:$O$55,">="&D22)>1,"⚠️ 기간 중복","정상"))) | O22: =IF(C22="","",IF(E22="",DATE(2099,12,31),E22))
B23: =IF(C23="","",ROW()-5) | L23: =IF(C23="","",G23+SUM(I23:K23)) | M23: =IF(C23="","",H23+SUM(I23:K23)) | N23: =IF(C23="","",IF(D23>O23,"⚠️ 시작일>종료일 오류",IF(COUNTIFS($C$6:$C$55,C23,$D$6:$D$55,"<="&O23,$O$6:$O$55,">="&D23)>1,"⚠️ 기간 중복","정상"))) | O23: =IF(C23="","",IF(E23="",DATE(2099,12,31),E23))
B24: =IF(C24="","",ROW()-5) | L24: =IF(C24="","",G24+SUM(I24:K24)) | M24: =IF(C24="","",H24+SUM(I24:K24)) | N24: =IF(C24="","",IF(D24>O24,"⚠️ 시작일>종료일 오류",IF(COUNTIFS($C$6:$C$55,C24,$D$6:$D$55,"<="&O24,$O$6:$O$55,">="&D24)>1,"⚠️ 기간 중복","정상"))) | O24: =IF(C24="","",IF(E24="",DATE(2099,12,31),E24))
B25: =IF(C25="","",ROW()-5) | L25: =IF(C25="","",G25+SUM(I25:K25)) | M25: =IF(C25="","",H25+SUM(I25:K25)) | N25: =IF(C25="","",IF(D25>O25,"⚠️ 시작일>종료일 오류",IF(COUNTIFS($C$6:$C$55,C25,$D$6:$D$55,"<="&O25,$O$6:$O$55,">="&D25)>1,"⚠️ 기간 중복","정상"))) | O25: =IF(C25="","",IF(E25="",DATE(2099,12,31),E25))
... B55: =IF(C55="","",ROW()-5) | L55: =IF(C55="","",G55+SUM(I55:K55)) | M55: =IF(C55="","",H55+SUM(I55:K55)) | N55: =IF(C55="","",IF(D55>O55,"⚠️ 시작일>종료일 오류",IF(COUNTIFS($C$6:$C$55,C55,$D$6:$D$55,"<="&O55,$O$6:$O$55,">="&D55)>1,"⚠️ 기간 중복","정상"))) | O55: =IF(C55="","",IF(E55="",DATE(2099,12,31),E55))

Sheet 4_판매채널별_손익분석
B2: 매출·지출관리 스프레드시트(순이익/실적 자동계산) | 판매채널별 손익 상세 분석
B3: 연동 시작일 | C3: 연동 종료일 | D3: 표/그래프 정렬 기준 (드롭다운) | G3: 공통비용 배분 기준 | I3: 기간 공통비용 합계 | J3: 안내 사항
B4: ='1_매출손익_대시보드'!F4 -> 46327 | C4: ='1_매출손익_대시보드'!G4 -> 46356 | D4: 순이익 높은순 | G4: ='5_목표매출_및_공통비용'!K4 -> 매출액 비중 배분 | I4: ='5_목표매출_및_공통비용'!M26 -> 800000 | J4: 💡 판매채널별 10kg 미만/이상 주문건수와 비용·순이익을 분석합니다. 적자(<0) 항목은 붉은색으로 강조됩니다.
B6: 🛒 판매채널별 손익 분석표 (매출액순 / 순이익순 자동 정렬) | R6: [자동정렬용 원본 집계 데이터]
B7: 순위 | C7: 판매채널명 | D7: 10kg 미만 주문건수 | E7: 10kg 이상 주문건수 | F7: 총 주문건수 | G7: 매출액 (원) | H7: 매출 비중 | I7: 매출액 수수료 | J7: 주문건수 비용 (택배+박스+비닐+리플렛) | K7: 추가 비용 | L7: 총비용 (공통비 제외) | M7: 순이익 (공통비 전) | N7: 순이익률 (공통비 전) | O7: 공통비용 배분액 | P7: 최종 순이익 (공통비 후) | R7: 정렬점수 | S7: 채널명 | T7: 미만건수 | U7: 이상건수 | V7: 총건수 | W7: 매출액 | X7: 매출수수료 | Y7: 건수비용 | Z7: 추가비용 | AA7: 총비용 | AB7: 순이익
B8: 1 | C8: =INDEX($S$8:$S$14,MATCH(LARGE($R$8:$R$14,B8),$R$8:$R$14,0)) -> 농라 | D8: =INDEX($T$8:$T$14,MATCH(LARGE($R$8:$R$14,B8),$R$8:$R$14,0)) -> 52 | E8: =INDEX($U$8:$U$14,MATCH(LARGE($R$8:$R$14,B8),$R$8:$R$14,0)) -> 27 | F8: =D8+E8 -> 79 | G8: =INDEX($W$8:$W$14,MATCH(LARGE($R$8:$R$14,B8),$R$8:$R$14,0)) -> 3330000 | H8: =IFERROR(G8/$G$15,0) -> 0.22957601 | I8: =INDEX($X$8:$X$14,MATCH(LARGE($R$8:$R$14,B8),$R$8:$R$14,0)) -> 0 | J8: =INDEX($Y$8:$Y$14,MATCH(LARGE($R$8:$R$14,B8),$R$8:$R$14,0)) -> 374600 | K8: =INDEX($Z$8:$Z$14,MATCH(LARGE($R$8:$R$14,B8),$R$8:$R$14,0)) -> 15000 | L8: =SUM(I8:K8) -> 389600 | M8: =G8-L8 -> 2940400 | N8: =IFERROR(M8/G8,0) -> 0.883003 | O8: =IF($G$4="매출액 비중 배분",ROUND($I$4*H8,0),IF($G$4="주문건수 비중 배분",ROUND($I$4*IFERROR(F8/$F$15,0),0),0)) -> 183661 | P8: =M8-O8 -> 2756739 | R8: =IF($D$4="매출액 높은순",W8,IF($D$4="순이익 높은순",AB8,-ROW()))+(100-ROW())*0.00001 -> 2940400 | S8: ='6_사용설명서_및_기준관리'!B6 -> 농라 | T8: =SUMIFS('2_일일매출_입력'!$D$6:$D$305,'2_일일매출_입력'!$C$6:$C$305,S8,'2_일일매출_입력'!$B$6:$B$305,">="&$B$4,'2_일일매출_입력'!$B$6:$B$305,"<="&$C$4) -> 52 | U8: =SUMIFS('2_일일매출_입력'!$E$6:$E$305,'2_일일매출_입력'!$C$6:$C$305,S8,'2_일일매출_입력'!$B$6:$B$305,">="&$B$4,'2_일일매출_입력'!$B$6:$B$305,"<="&$C$4) -> 27 | V8: =T8+U8 -> 79 | W8: =SUMIFS('2_일일매출_입력'!$G$6:$G$305,'2_일일매출_입력'!$C$6:$C$305,S8,'2_일일매출_입력'!$B$6:$B$305,">="&$B$4,'2_일일매출_입력'!$B$6:$B$305,"<="&$C$4) -> 3330000 | X8: =SUMIFS('2_일일매출_입력'!$L$6:$L$305,'2_일일매출_입력'!$C$6:$C$305,S8,'2_일일매출_입력'!$B$6:$B$305,">="&$B$4,'2_일일매출_입력'!$B$6:$B$305,"<="&$C$4) -> 0 | Y8: =SUMIFS('2_일일매출_입력'!$O$6:$O$305,'2_일일매출_입력'!$C$6:$C$305,S8,'2_일일매출_입력'!$B$6:$B$305,">="&$B$4,'2_일일매출_입력'!$B$6:$B$305,"<="&$C$4) -> 374600 | Z8: =SUMIFS('2_일일매출_입력'!$H$6:$H$305,'2_일일매출_입력'!$C$6:$C$305,S8,'2_일일매출_입력'!$B$6:$B$305,">="&$B$4,'2_일일매출_입력'!$B$6:$B$305,"<="&$C$4) -> 15000 | AA8: =SUM(X8:Z8) -> 389600 | AB8: =W8-AA8 -> 2940400
